[2022-09-11 09:32:03,839] {taskinstance.py:1032} INFO - Dependencies all met for <TaskInstance: ZonesIngestionDag.ingest manual__2022-09-11T09:31:26.068892+00:00 [queued]>
[2022-09-11 09:32:03,853] {taskinstance.py:1032} INFO - Dependencies all met for <TaskInstance: ZonesIngestionDag.ingest manual__2022-09-11T09:31:26.068892+00:00 [queued]>
[2022-09-11 09:32:03,854] {taskinstance.py:1238} INFO - 
--------------------------------------------------------------------------------
[2022-09-11 09:32:03,854] {taskinstance.py:1239} INFO - Starting attempt 1 of 1
[2022-09-11 09:32:03,855] {taskinstance.py:1240} INFO - 
--------------------------------------------------------------------------------
[2022-09-11 09:32:04,055] {taskinstance.py:1259} INFO - Executing <Task(PythonOperator): ingest> on 2022-09-11 09:31:26.068892+00:00
[2022-09-11 09:32:04,060] {standard_task_runner.py:52} INFO - Started process 6311 to run task
[2022-09-11 09:32:04,064] {standard_task_runner.py:76} INFO - Running: ['***', 'tasks', 'run', 'ZonesIngestionDag', 'ingest', 'manual__2022-09-11T09:31:26.068892+00:00', '--job-id', '21', '--raw', '--subdir', 'DAGS_FOLDER/Zones_ingest.py', '--cfg-path', '/tmp/tmpfo843_qe', '--error-file', '/tmp/tmpn39fz0hp']
[2022-09-11 09:32:04,065] {standard_task_runner.py:77} INFO - Job 21: Subtask ingest
[2022-09-11 09:32:04,373] {logging_mixin.py:109} INFO - Running <TaskInstance: ZonesIngestionDag.ingest manual__2022-09-11T09:31:26.068892+00:00 [running]> on host 6ae512137983
[2022-09-11 09:32:04,692] {taskinstance.py:1426} INFO - Exporting the following env vars:
AIRFLOW_CTX_DAG_OWNER=***
AIRFLOW_CTX_DAG_ID=ZonesIngestionDag
AIRFLOW_CTX_TASK_ID=ingest
AIRFLOW_CTX_EXECUTION_DATE=2022-09-11T09:31:26.068892+00:00
AIRFLOW_CTX_DAG_RUN_ID=manual__2022-09-11T09:31:26.068892+00:00
[2022-09-11 09:32:04,736] {taskinstance.py:1700} ERROR - Task failed with exception
Traceback (most recent call last):
  File "/home/airflow/.local/lib/python3.7/site-packages/airflow/models/taskinstance.py", line 1329, in _run_raw_task
    self._execute_task_with_callbacks(context)
  File "/home/airflow/.local/lib/python3.7/site-packages/airflow/models/taskinstance.py", line 1455, in _execute_task_with_callbacks
    result = self._execute_task(context, self.task)
  File "/home/airflow/.local/lib/python3.7/site-packages/airflow/models/taskinstance.py", line 1511, in _execute_task
    result = execute_callable(context=context)
  File "/home/airflow/.local/lib/python3.7/site-packages/airflow/operators/python.py", line 174, in execute
    return_value = self.execute_callable()
  File "/home/airflow/.local/lib/python3.7/site-packages/airflow/operators/python.py", line 185, in execute_callable
    return self.python_callable(*self.op_args, **self.op_kwargs)
  File "/opt/airflow/dags/callable_script.py", line 14, in ingest_call
    outparq[["tpep_pickup_datetime","tpep_dropoff_datetime"]] = outparq[["tpep_pickup_datetime","tpep_dropoff_datetime"]].apply(pd.to_datetime)
  File "/home/airflow/.local/lib/python3.7/site-packages/pandas/core/frame.py", line 3464, in __getitem__
    indexer = self.loc._get_listlike_indexer(key, axis=1)[1]
  File "/home/airflow/.local/lib/python3.7/site-packages/pandas/core/indexing.py", line 1314, in _get_listlike_indexer
    self._validate_read_indexer(keyarr, indexer, axis)
  File "/home/airflow/.local/lib/python3.7/site-packages/pandas/core/indexing.py", line 1374, in _validate_read_indexer
    raise KeyError(f"None of [{key}] are in the [{axis_name}]")
KeyError: "None of [Index(['tpep_pickup_datetime', 'tpep_dropoff_datetime'], dtype='object')] are in the [columns]"
[2022-09-11 09:32:04,753] {taskinstance.py:1277} INFO - Marking task as FAILED. dag_id=ZonesIngestionDag, task_id=ingest, execution_date=20220911T093126, start_date=20220911T093203, end_date=20220911T093204
[2022-09-11 09:32:04,900] {standard_task_runner.py:92} ERROR - Failed to execute job 21 for task ingest
Traceback (most recent call last):
  File "/home/airflow/.local/lib/python3.7/site-packages/airflow/task/task_runner/standard_task_runner.py", line 85, in _start_by_fork
    args.func(args, dag=self.dag)
  File "/home/airflow/.local/lib/python3.7/site-packages/airflow/cli/cli_parser.py", line 48, in command
    return func(*args, **kwargs)
  File "/home/airflow/.local/lib/python3.7/site-packages/airflow/utils/cli.py", line 92, in wrapper
    return f(*args, **kwargs)
  File "/home/airflow/.local/lib/python3.7/site-packages/airflow/cli/commands/task_command.py", line 298, in task_run
    _run_task_by_selected_method(args, dag, ti)
  File "/home/airflow/.local/lib/python3.7/site-packages/airflow/cli/commands/task_command.py", line 107, in _run_task_by_selected_method
    _run_raw_task(args, ti)
  File "/home/airflow/.local/lib/python3.7/site-packages/airflow/cli/commands/task_command.py", line 184, in _run_raw_task
    error_file=args.error_file,
  File "/home/airflow/.local/lib/python3.7/site-packages/airflow/utils/session.py", line 70, in wrapper
    return func(*args, session=session, **kwargs)
  File "/home/airflow/.local/lib/python3.7/site-packages/airflow/models/taskinstance.py", line 1329, in _run_raw_task
    self._execute_task_with_callbacks(context)
  File "/home/airflow/.local/lib/python3.7/site-packages/airflow/models/taskinstance.py", line 1455, in _execute_task_with_callbacks
    result = self._execute_task(context, self.task)
  File "/home/airflow/.local/lib/python3.7/site-packages/airflow/models/taskinstance.py", line 1511, in _execute_task
    result = execute_callable(context=context)
  File "/home/airflow/.local/lib/python3.7/site-packages/airflow/operators/python.py", line 174, in execute
    return_value = self.execute_callable()
  File "/home/airflow/.local/lib/python3.7/site-packages/airflow/operators/python.py", line 185, in execute_callable
    return self.python_callable(*self.op_args, **self.op_kwargs)
  File "/opt/airflow/dags/callable_script.py", line 14, in ingest_call
    outparq[["tpep_pickup_datetime","tpep_dropoff_datetime"]] = outparq[["tpep_pickup_datetime","tpep_dropoff_datetime"]].apply(pd.to_datetime)
  File "/home/airflow/.local/lib/python3.7/site-packages/pandas/core/frame.py", line 3464, in __getitem__
    indexer = self.loc._get_listlike_indexer(key, axis=1)[1]
  File "/home/airflow/.local/lib/python3.7/site-packages/pandas/core/indexing.py", line 1314, in _get_listlike_indexer
    self._validate_read_indexer(keyarr, indexer, axis)
  File "/home/airflow/.local/lib/python3.7/site-packages/pandas/core/indexing.py", line 1374, in _validate_read_indexer
    raise KeyError(f"None of [{key}] are in the [{axis_name}]")
KeyError: "None of [Index(['tpep_pickup_datetime', 'tpep_dropoff_datetime'], dtype='object')] are in the [columns]"
[2022-09-11 09:32:04,925] {local_task_job.py:154} INFO - Task exited with return code 1
[2022-09-11 09:32:05,108] {local_task_job.py:264} INFO - 0 downstream tasks scheduled from follow-on schedule check
