[2022-09-17 02:15:14,409] {taskinstance.py:1032} INFO - Dependencies all met for <TaskInstance: LocalIngestionDag.ingest scheduled__2019-01-01T06:00:00+00:00 [queued]>
[2022-09-17 02:15:14,420] {taskinstance.py:1032} INFO - Dependencies all met for <TaskInstance: LocalIngestionDag.ingest scheduled__2019-01-01T06:00:00+00:00 [queued]>
[2022-09-17 02:15:14,420] {taskinstance.py:1238} INFO - 
--------------------------------------------------------------------------------
[2022-09-17 02:15:14,421] {taskinstance.py:1239} INFO - Starting attempt 11 of 11
[2022-09-17 02:15:14,421] {taskinstance.py:1240} INFO - 
--------------------------------------------------------------------------------
[2022-09-17 02:15:14,615] {taskinstance.py:1259} INFO - Executing <Task(PythonOperator): ingest> on 2019-01-01 06:00:00+00:00
[2022-09-17 02:15:14,619] {standard_task_runner.py:52} INFO - Started process 894 to run task
[2022-09-17 02:15:14,623] {standard_task_runner.py:76} INFO - Running: ['***', 'tasks', 'run', 'LocalIngestionDag', 'ingest', 'scheduled__2019-01-01T06:00:00+00:00', '--job-id', '248', '--raw', '--subdir', 'DAGS_FOLDER/ingest_data_dag.py', '--cfg-path', '/tmp/tmp2a130m7h', '--error-file', '/tmp/tmp3reklytb']
[2022-09-17 02:15:14,624] {standard_task_runner.py:77} INFO - Job 248: Subtask ingest
[2022-09-17 02:15:14,837] {logging_mixin.py:109} INFO - Running <TaskInstance: LocalIngestionDag.ingest scheduled__2019-01-01T06:00:00+00:00 [running]> on host 5d94276fbe2b
[2022-09-17 02:15:15,121] {logging_mixin.py:109} WARNING - /home/***/.local/lib/python3.7/site-packages/***/utils/context.py:152 AirflowContextDeprecationWarning: Accessing 'execution_date' from the template is deprecated and will be removed in a future version. Please use 'data_interval_start' or 'logical_date' instead.
[2022-09-17 02:15:15,146] {taskinstance.py:1426} INFO - Exporting the following env vars:
AIRFLOW_CTX_DAG_OWNER=***
AIRFLOW_CTX_DAG_ID=LocalIngestionDag
AIRFLOW_CTX_TASK_ID=ingest
AIRFLOW_CTX_EXECUTION_DATE=2019-01-01T06:00:00+00:00
AIRFLOW_CTX_DAG_RUN_ID=scheduled__2019-01-01T06:00:00+00:00
[2022-09-17 02:15:15,149] {logging_mixin.py:109} INFO - root   root   docker_sql_0_pgdatabase_1   5432   ny_taxi   yellow_taxi_2019_01   /opt/***/output_2019-01.parquet
[2022-09-17 02:16:28,943] {base_job.py:230} ERROR - LocalTaskJob heartbeat got an exception
Traceback (most recent call last):
  File "/home/airflow/.local/lib/python3.7/site-packages/sqlalchemy/engine/base.py", line 2336, in _wrap_pool_connect
    return fn()
  File "/home/airflow/.local/lib/python3.7/site-packages/sqlalchemy/pool/base.py", line 364, in connect
    return _ConnectionFairy._checkout(self)
  File "/home/airflow/.local/lib/python3.7/site-packages/sqlalchemy/pool/base.py", line 778, in _checkout
    fairy = _ConnectionRecord.checkout(pool)
  File "/home/airflow/.local/lib/python3.7/site-packages/sqlalchemy/pool/base.py", line 495, in checkout
    rec = pool._do_get()
  File "/home/airflow/.local/lib/python3.7/site-packages/sqlalchemy/pool/impl.py", line 241, in _do_get
    return self._create_connection()
  File "/home/airflow/.local/lib/python3.7/site-packages/sqlalchemy/pool/base.py", line 309, in _create_connection
    return _ConnectionRecord(self)
  File "/home/airflow/.local/lib/python3.7/site-packages/sqlalchemy/pool/base.py", line 440, in __init__
    self.__connect(first_connect_check=True)
  File "/home/airflow/.local/lib/python3.7/site-packages/sqlalchemy/pool/base.py", line 661, in __connect
    pool.logger.debug("Error on connect(): %s", e)
  File "/home/airflow/.local/lib/python3.7/site-packages/sqlalchemy/util/langhelpers.py", line 70, in __exit__
    with_traceback=exc_tb,
  File "/home/airflow/.local/lib/python3.7/site-packages/sqlalchemy/util/compat.py", line 182, in raise_
    raise exception
  File "/home/airflow/.local/lib/python3.7/site-packages/sqlalchemy/pool/base.py", line 656, in __connect
    connection = pool._invoke_creator(self)
  File "/home/airflow/.local/lib/python3.7/site-packages/sqlalchemy/engine/strategies.py", line 114, in connect
    return dialect.connect(*cargs, **cparams)
  File "/home/airflow/.local/lib/python3.7/site-packages/sqlalchemy/engine/default.py", line 508, in connect
    return self.dbapi.connect(*cargs, **cparams)
  File "/home/airflow/.local/lib/python3.7/site-packages/psycopg2/__init__.py", line 122, in connect
    conn = _connect(dsn, connection_factory=connection_factory, **kwasync)
psycopg2.OperationalError: could not translate host name "postgres" to address: Temporary failure in name resolution


The above exception was the direct cause of the following exception:

Traceback (most recent call last):
  File "/home/airflow/.local/lib/python3.7/site-packages/airflow/jobs/base_job.py", line 220, in heartbeat
    session.merge(self)
  File "/home/airflow/.local/lib/python3.7/site-packages/sqlalchemy/orm/session.py", line 2171, in merge
    _resolve_conflict_map=_resolve_conflict_map,
  File "/home/airflow/.local/lib/python3.7/site-packages/sqlalchemy/orm/session.py", line 2244, in _merge
    merged = self.query(mapper.class_).get(key[1])
  File "/home/airflow/.local/lib/python3.7/site-packages/sqlalchemy/orm/query.py", line 1018, in get
    return self._get_impl(ident, loading.load_on_pk_identity)
  File "/home/airflow/.local/lib/python3.7/site-packages/sqlalchemy/orm/query.py", line 1135, in _get_impl
    return db_load_fn(self, primary_key_identity)
  File "/home/airflow/.local/lib/python3.7/site-packages/sqlalchemy/orm/loading.py", line 286, in load_on_pk_identity
    return q.one()
  File "/home/airflow/.local/lib/python3.7/site-packages/sqlalchemy/orm/query.py", line 3490, in one
    ret = self.one_or_none()
  File "/home/airflow/.local/lib/python3.7/site-packages/sqlalchemy/orm/query.py", line 3459, in one_or_none
    ret = list(self)
  File "/home/airflow/.local/lib/python3.7/site-packages/sqlalchemy/orm/query.py", line 3535, in __iter__
    return self._execute_and_instances(context)
  File "/home/airflow/.local/lib/python3.7/site-packages/sqlalchemy/orm/query.py", line 3557, in _execute_and_instances
    querycontext, self._connection_from_session, close_with_result=True
  File "/home/airflow/.local/lib/python3.7/site-packages/sqlalchemy/orm/query.py", line 3572, in _get_bind_args
    mapper=self._bind_mapper(), clause=querycontext.statement, **kw
  File "/home/airflow/.local/lib/python3.7/site-packages/sqlalchemy/orm/query.py", line 3550, in _connection_from_session
    conn = self.session.connection(**kw)
  File "/home/airflow/.local/lib/python3.7/site-packages/sqlalchemy/orm/session.py", line 1145, in connection
    execution_options=execution_options,
  File "/home/airflow/.local/lib/python3.7/site-packages/sqlalchemy/orm/session.py", line 1151, in _connection_for_bind
    engine, execution_options
  File "/home/airflow/.local/lib/python3.7/site-packages/sqlalchemy/orm/session.py", line 433, in _connection_for_bind
    conn = bind._contextual_connect()
  File "/home/airflow/.local/lib/python3.7/site-packages/sqlalchemy/engine/base.py", line 2302, in _contextual_connect
    self._wrap_pool_connect(self.pool.connect, None),
  File "/home/airflow/.local/lib/python3.7/site-packages/sqlalchemy/engine/base.py", line 2340, in _wrap_pool_connect
    e, dialect, self
  File "/home/airflow/.local/lib/python3.7/site-packages/sqlalchemy/engine/base.py", line 1584, in _handle_dbapi_exception_noconnection
    sqlalchemy_exception, with_traceback=exc_info[2], from_=e
  File "/home/airflow/.local/lib/python3.7/site-packages/sqlalchemy/util/compat.py", line 182, in raise_
    raise exception
  File "/home/airflow/.local/lib/python3.7/site-packages/sqlalchemy/engine/base.py", line 2336, in _wrap_pool_connect
    return fn()
  File "/home/airflow/.local/lib/python3.7/site-packages/sqlalchemy/pool/base.py", line 364, in connect
    return _ConnectionFairy._checkout(self)
  File "/home/airflow/.local/lib/python3.7/site-packages/sqlalchemy/pool/base.py", line 778, in _checkout
    fairy = _ConnectionRecord.checkout(pool)
  File "/home/airflow/.local/lib/python3.7/site-packages/sqlalchemy/pool/base.py", line 495, in checkout
    rec = pool._do_get()
  File "/home/airflow/.local/lib/python3.7/site-packages/sqlalchemy/pool/impl.py", line 241, in _do_get
    return self._create_connection()
  File "/home/airflow/.local/lib/python3.7/site-packages/sqlalchemy/pool/base.py", line 309, in _create_connection
    return _ConnectionRecord(self)
  File "/home/airflow/.local/lib/python3.7/site-packages/sqlalchemy/pool/base.py", line 440, in __init__
    self.__connect(first_connect_check=True)
  File "/home/airflow/.local/lib/python3.7/site-packages/sqlalchemy/pool/base.py", line 661, in __connect
    pool.logger.debug("Error on connect(): %s", e)
  File "/home/airflow/.local/lib/python3.7/site-packages/sqlalchemy/util/langhelpers.py", line 70, in __exit__
    with_traceback=exc_tb,
  File "/home/airflow/.local/lib/python3.7/site-packages/sqlalchemy/util/compat.py", line 182, in raise_
    raise exception
  File "/home/airflow/.local/lib/python3.7/site-packages/sqlalchemy/pool/base.py", line 656, in __connect
    connection = pool._invoke_creator(self)
  File "/home/airflow/.local/lib/python3.7/site-packages/sqlalchemy/engine/strategies.py", line 114, in connect
    return dialect.connect(*cargs, **cparams)
  File "/home/airflow/.local/lib/python3.7/site-packages/sqlalchemy/engine/default.py", line 508, in connect
    return self.dbapi.connect(*cargs, **cparams)
  File "/home/airflow/.local/lib/python3.7/site-packages/psycopg2/__init__.py", line 122, in connect
    conn = _connect(dsn, connection_factory=connection_factory, **kwasync)
sqlalchemy.exc.OperationalError: (psycopg2.OperationalError) could not translate host name "postgres" to address: Temporary failure in name resolution

(Background on this error at: http://sqlalche.me/e/13/e3q8)
[2022-09-17 02:16:39,519] {local_task_job.py:154} INFO - Task exited with return code Negsignal.SIGKILL
[2022-09-17 02:16:41,898] {taskinstance.py:1277} INFO - Marking task as FAILED. dag_id=LocalIngestionDag, task_id=ingest, execution_date=20190101T060000, start_date=20220917T021514, end_date=20220917T021641
[2022-09-17 02:16:43,547] {local_task_job.py:264} INFO - 0 downstream tasks scheduled from follow-on schedule check
[2022-09-17 02:16:43,581] {dagrun.py:530} ERROR - Marking run <DagRun LocalIngestionDag @ 2019-01-01 06:00:00+00:00: scheduled__2019-01-01T06:00:00+00:00, externally triggered: False> failed
[2022-09-17 02:16:43,582] {dagrun.py:605} INFO - DagRun Finished: dag_id=LocalIngestionDag, execution_date=2019-01-01 06:00:00+00:00, run_id=scheduled__2019-01-01T06:00:00+00:00, run_start_date=2022-09-17 02:15:05.130332+00:00, run_end_date=2022-09-17 02:16:43.582678+00:00, run_duration=98.452346, state=failed, external_trigger=False, run_type=scheduled, data_interval_start=2019-01-01 06:00:00+00:00, data_interval_end=2019-02-01 06:00:00+00:00, dag_hash=6059d761a110d1304e9bdc6239d9f30f
[2022-09-17 03:34:45,554] {taskinstance.py:1032} INFO - Dependencies all met for <TaskInstance: LocalIngestionDag.ingest scheduled__2019-01-01T06:00:00+00:00 [queued]>
[2022-09-17 03:34:45,614] {taskinstance.py:1032} INFO - Dependencies all met for <TaskInstance: LocalIngestionDag.ingest scheduled__2019-01-01T06:00:00+00:00 [queued]>
[2022-09-17 03:34:45,615] {taskinstance.py:1238} INFO - 
--------------------------------------------------------------------------------
[2022-09-17 03:34:45,615] {taskinstance.py:1239} INFO - Starting attempt 11 of 11
[2022-09-17 03:34:45,617] {taskinstance.py:1240} INFO - 
--------------------------------------------------------------------------------
[2022-09-17 03:34:45,681] {taskinstance.py:1259} INFO - Executing <Task(PythonOperator): ingest> on 2019-01-01 06:00:00+00:00
[2022-09-17 03:34:45,685] {standard_task_runner.py:52} INFO - Started process 7993 to run task
[2022-09-17 03:34:45,689] {standard_task_runner.py:76} INFO - Running: ['***', 'tasks', 'run', 'LocalIngestionDag', 'ingest', 'scheduled__2019-01-01T06:00:00+00:00', '--job-id', '267', '--raw', '--subdir', 'DAGS_FOLDER/ingest_data_dag.py', '--cfg-path', '/tmp/tmpx0diq06v', '--error-file', '/tmp/tmpxxdomcfm']
[2022-09-17 03:34:45,690] {standard_task_runner.py:77} INFO - Job 267: Subtask ingest
[2022-09-17 03:34:45,791] {logging_mixin.py:109} INFO - Running <TaskInstance: LocalIngestionDag.ingest scheduled__2019-01-01T06:00:00+00:00 [running]> on host 5d94276fbe2b
[2022-09-17 03:34:45,965] {logging_mixin.py:109} WARNING - /home/***/.local/lib/python3.7/site-packages/***/utils/context.py:152 AirflowContextDeprecationWarning: Accessing 'execution_date' from the template is deprecated and will be removed in a future version. Please use 'data_interval_start' or 'logical_date' instead.
[2022-09-17 03:34:45,983] {taskinstance.py:1426} INFO - Exporting the following env vars:
AIRFLOW_CTX_DAG_OWNER=***
AIRFLOW_CTX_DAG_ID=LocalIngestionDag
AIRFLOW_CTX_TASK_ID=ingest
AIRFLOW_CTX_EXECUTION_DATE=2019-01-01T06:00:00+00:00
AIRFLOW_CTX_DAG_RUN_ID=scheduled__2019-01-01T06:00:00+00:00
[2022-09-17 03:34:45,984] {logging_mixin.py:109} INFO - root   root   docker_sql_0_pgdatabase_1   5432   ny_taxi   yellow_taxi_2019_01   /opt/***/output_2019-01.parquet
[2022-09-17 03:35:32,089] {local_task_job.py:154} INFO - Task exited with return code Negsignal.SIGKILL
[2022-09-17 03:35:32,116] {taskinstance.py:1277} INFO - Marking task as FAILED. dag_id=LocalIngestionDag, task_id=ingest, execution_date=20190101T060000, start_date=20220917T033445, end_date=20220917T033532
[2022-09-17 03:35:32,745] {local_task_job.py:264} INFO - 0 downstream tasks scheduled from follow-on schedule check
[2022-09-17 03:35:32,817] {dagrun.py:628} WARNING - Failed to get task '<TaskInstance: LocalIngestionDag.eng scheduled__2019-01-01T06:00:00+00:00 [removed]>' for dag 'LocalIngestionDag'. Marking it as removed.
[2022-09-17 03:35:32,819] {dagrun.py:530} ERROR - Marking run <DagRun LocalIngestionDag @ 2019-01-01 06:00:00+00:00: scheduled__2019-01-01T06:00:00+00:00, externally triggered: False> failed
[2022-09-17 03:35:32,827] {dagrun.py:605} INFO - DagRun Finished: dag_id=LocalIngestionDag, execution_date=2019-01-01 06:00:00+00:00, run_id=scheduled__2019-01-01T06:00:00+00:00, run_start_date=2022-09-17 03:34:43.488006+00:00, run_end_date=2022-09-17 03:35:32.827541+00:00, run_duration=49.339535, state=failed, external_trigger=False, run_type=scheduled, data_interval_start=2019-01-01 06:00:00+00:00, data_interval_end=2019-02-01 06:00:00+00:00, dag_hash=6059d761a110d1304e9bdc6239d9f30f
