[2022-09-11 16:41:20,001] {taskinstance.py:1032} INFO - Dependencies all met for <TaskInstance: FHVIngestionDag.ingest scheduled__2019-07-01T06:00:00+00:00 [queued]>
[2022-09-11 16:41:20,014] {taskinstance.py:1032} INFO - Dependencies all met for <TaskInstance: FHVIngestionDag.ingest scheduled__2019-07-01T06:00:00+00:00 [queued]>
[2022-09-11 16:41:20,015] {taskinstance.py:1238} INFO - 
--------------------------------------------------------------------------------
[2022-09-11 16:41:20,016] {taskinstance.py:1239} INFO - Starting attempt 1 of 1
[2022-09-11 16:41:20,016] {taskinstance.py:1240} INFO - 
--------------------------------------------------------------------------------
[2022-09-11 16:41:20,161] {taskinstance.py:1259} INFO - Executing <Task(PythonOperator): ingest> on 2019-07-01 06:00:00+00:00
[2022-09-11 16:41:20,208] {standard_task_runner.py:52} INFO - Started process 7884 to run task
[2022-09-11 16:41:20,227] {standard_task_runner.py:76} INFO - Running: ['***', 'tasks', 'run', 'FHVIngestionDag', 'ingest', 'scheduled__2019-07-01T06:00:00+00:00', '--job-id', '91', '--raw', '--subdir', 'DAGS_FOLDER/FHV_ingest_19.py', '--cfg-path', '/tmp/tmpub8n6el_', '--error-file', '/tmp/tmp4rt6gtyq']
[2022-09-11 16:41:20,230] {standard_task_runner.py:77} INFO - Job 91: Subtask ingest
[2022-09-11 16:41:20,425] {logging_mixin.py:109} INFO - Running <TaskInstance: FHVIngestionDag.ingest scheduled__2019-07-01T06:00:00+00:00 [running]> on host 6ae512137983
[2022-09-11 16:41:20,610] {logging_mixin.py:109} WARNING - /home/***/.local/lib/python3.7/site-packages/***/utils/context.py:152 AirflowContextDeprecationWarning: Accessing 'execution_date' from the template is deprecated and will be removed in a future version. Please use 'data_interval_start' or 'logical_date' instead.
[2022-09-11 16:41:20,759] {taskinstance.py:1426} INFO - Exporting the following env vars:
AIRFLOW_CTX_DAG_OWNER=***
AIRFLOW_CTX_DAG_ID=FHVIngestionDag
AIRFLOW_CTX_TASK_ID=ingest
AIRFLOW_CTX_EXECUTION_DATE=2019-07-01T06:00:00+00:00
AIRFLOW_CTX_DAG_RUN_ID=scheduled__2019-07-01T06:00:00+00:00
[2022-09-11 16:41:28,303] {taskinstance.py:1700} ERROR - Task failed with exception
Traceback (most recent call last):
  File "/home/airflow/.local/lib/python3.7/site-packages/airflow/models/taskinstance.py", line 1329, in _run_raw_task
    self._execute_task_with_callbacks(context)
  File "/home/airflow/.local/lib/python3.7/site-packages/airflow/models/taskinstance.py", line 1455, in _execute_task_with_callbacks
    result = self._execute_task(context, self.task)
  File "/home/airflow/.local/lib/python3.7/site-packages/airflow/models/taskinstance.py", line 1511, in _execute_task
    result = execute_callable(context=context)
  File "/home/airflow/.local/lib/python3.7/site-packages/airflow/operators/python.py", line 174, in execute
    return_value = self.execute_callable()
  File "/home/airflow/.local/lib/python3.7/site-packages/airflow/operators/python.py", line 185, in execute_callable
    return self.python_callable(*self.op_args, **self.op_kwargs)
  File "/opt/airflow/dags/FHV_ingest_19.py", line 22, in ingest_call
    outparq = pd.read_parquet(filePath)
  File "/home/airflow/.local/lib/python3.7/site-packages/pandas/io/parquet.py", line 500, in read_parquet
    **kwargs,
  File "/home/airflow/.local/lib/python3.7/site-packages/pandas/io/parquet.py", line 241, in read
    ).to_pandas(**to_pandas_kwargs)
  File "pyarrow/array.pxi", line 757, in pyarrow.lib._PandasConvertible.to_pandas
  File "pyarrow/table.pxi", line 1748, in pyarrow.lib.Table._to_pandas
  File "/home/airflow/.local/lib/python3.7/site-packages/pyarrow/pandas_compat.py", line 789, in table_to_blockmanager
    blocks = _table_to_blocks(options, table, categories, ext_columns_dtypes)
  File "/home/airflow/.local/lib/python3.7/site-packages/pyarrow/pandas_compat.py", line 1129, in _table_to_blocks
    list(extension_columns.keys()))
  File "pyarrow/table.pxi", line 1156, in pyarrow.lib.table_to_blocks
  File "pyarrow/error.pxi", line 99, in pyarrow.lib.check_status
pyarrow.lib.ArrowInvalid: Casting from timestamp[us] to timestamp[ns] would result in out of bounds timestamp: 33119051544000000
[2022-09-11 16:41:29,103] {taskinstance.py:1277} INFO - Marking task as FAILED. dag_id=FHVIngestionDag, task_id=ingest, execution_date=20190701T060000, start_date=20220911T164120, end_date=20220911T164129
[2022-09-11 16:41:29,192] {standard_task_runner.py:92} ERROR - Failed to execute job 91 for task ingest
Traceback (most recent call last):
  File "/home/airflow/.local/lib/python3.7/site-packages/airflow/task/task_runner/standard_task_runner.py", line 85, in _start_by_fork
    args.func(args, dag=self.dag)
  File "/home/airflow/.local/lib/python3.7/site-packages/airflow/cli/cli_parser.py", line 48, in command
    return func(*args, **kwargs)
  File "/home/airflow/.local/lib/python3.7/site-packages/airflow/utils/cli.py", line 92, in wrapper
    return f(*args, **kwargs)
  File "/home/airflow/.local/lib/python3.7/site-packages/airflow/cli/commands/task_command.py", line 298, in task_run
    _run_task_by_selected_method(args, dag, ti)
  File "/home/airflow/.local/lib/python3.7/site-packages/airflow/cli/commands/task_command.py", line 107, in _run_task_by_selected_method
    _run_raw_task(args, ti)
  File "/home/airflow/.local/lib/python3.7/site-packages/airflow/cli/commands/task_command.py", line 184, in _run_raw_task
    error_file=args.error_file,
  File "/home/airflow/.local/lib/python3.7/site-packages/airflow/utils/session.py", line 70, in wrapper
    return func(*args, session=session, **kwargs)
  File "/home/airflow/.local/lib/python3.7/site-packages/airflow/models/taskinstance.py", line 1329, in _run_raw_task
    self._execute_task_with_callbacks(context)
  File "/home/airflow/.local/lib/python3.7/site-packages/airflow/models/taskinstance.py", line 1455, in _execute_task_with_callbacks
    result = self._execute_task(context, self.task)
  File "/home/airflow/.local/lib/python3.7/site-packages/airflow/models/taskinstance.py", line 1511, in _execute_task
    result = execute_callable(context=context)
  File "/home/airflow/.local/lib/python3.7/site-packages/airflow/operators/python.py", line 174, in execute
    return_value = self.execute_callable()
  File "/home/airflow/.local/lib/python3.7/site-packages/airflow/operators/python.py", line 185, in execute_callable
    return self.python_callable(*self.op_args, **self.op_kwargs)
  File "/opt/airflow/dags/FHV_ingest_19.py", line 22, in ingest_call
    outparq = pd.read_parquet(filePath)
  File "/home/airflow/.local/lib/python3.7/site-packages/pandas/io/parquet.py", line 500, in read_parquet
    **kwargs,
  File "/home/airflow/.local/lib/python3.7/site-packages/pandas/io/parquet.py", line 241, in read
    ).to_pandas(**to_pandas_kwargs)
  File "pyarrow/array.pxi", line 757, in pyarrow.lib._PandasConvertible.to_pandas
  File "pyarrow/table.pxi", line 1748, in pyarrow.lib.Table._to_pandas
  File "/home/airflow/.local/lib/python3.7/site-packages/pyarrow/pandas_compat.py", line 789, in table_to_blockmanager
    blocks = _table_to_blocks(options, table, categories, ext_columns_dtypes)
  File "/home/airflow/.local/lib/python3.7/site-packages/pyarrow/pandas_compat.py", line 1129, in _table_to_blocks
    list(extension_columns.keys()))
  File "pyarrow/table.pxi", line 1156, in pyarrow.lib.table_to_blocks
  File "pyarrow/error.pxi", line 99, in pyarrow.lib.check_status
pyarrow.lib.ArrowInvalid: Casting from timestamp[us] to timestamp[ns] would result in out of bounds timestamp: 33119051544000000
[2022-09-11 16:41:29,293] {local_task_job.py:154} INFO - Task exited with return code 1
[2022-09-11 16:41:29,654] {local_task_job.py:264} INFO - 0 downstream tasks scheduled from follow-on schedule check
[2022-09-15 05:22:22,469] {taskinstance.py:1032} INFO - Dependencies all met for <TaskInstance: FHVIngestionDag.ingest scheduled__2019-07-01T06:00:00+00:00 [queued]>
[2022-09-15 05:22:22,493] {taskinstance.py:1032} INFO - Dependencies all met for <TaskInstance: FHVIngestionDag.ingest scheduled__2019-07-01T06:00:00+00:00 [queued]>
[2022-09-15 05:22:22,494] {taskinstance.py:1238} INFO - 
--------------------------------------------------------------------------------
[2022-09-15 05:22:22,494] {taskinstance.py:1239} INFO - Starting attempt 1 of 1
[2022-09-15 05:22:22,495] {taskinstance.py:1240} INFO - 
--------------------------------------------------------------------------------
[2022-09-15 05:22:22,545] {taskinstance.py:1259} INFO - Executing <Task(PythonOperator): ingest> on 2019-07-01 06:00:00+00:00
[2022-09-15 05:22:22,556] {standard_task_runner.py:52} INFO - Started process 644 to run task
[2022-09-15 05:22:22,568] {standard_task_runner.py:76} INFO - Running: ['***', 'tasks', 'run', 'FHVIngestionDag', 'ingest', 'scheduled__2019-07-01T06:00:00+00:00', '--job-id', '159', '--raw', '--subdir', 'DAGS_FOLDER/FHV_ingest_19.py', '--cfg-path', '/tmp/tmp2xw0x_4y', '--error-file', '/tmp/tmpua56vrm3']
[2022-09-15 05:22:22,571] {standard_task_runner.py:77} INFO - Job 159: Subtask ingest
[2022-09-15 05:22:22,692] {logging_mixin.py:109} INFO - Running <TaskInstance: FHVIngestionDag.ingest scheduled__2019-07-01T06:00:00+00:00 [running]> on host c071d865a623
[2022-09-15 05:22:22,827] {logging_mixin.py:109} WARNING - /home/***/.local/lib/python3.7/site-packages/***/utils/context.py:152 AirflowContextDeprecationWarning: Accessing 'execution_date' from the template is deprecated and will be removed in a future version. Please use 'data_interval_start' or 'logical_date' instead.
[2022-09-15 05:22:22,883] {taskinstance.py:1426} INFO - Exporting the following env vars:
AIRFLOW_CTX_DAG_OWNER=***
AIRFLOW_CTX_DAG_ID=FHVIngestionDag
AIRFLOW_CTX_TASK_ID=ingest
AIRFLOW_CTX_EXECUTION_DATE=2019-07-01T06:00:00+00:00
AIRFLOW_CTX_DAG_RUN_ID=scheduled__2019-07-01T06:00:00+00:00
[2022-09-15 05:22:22,884] {logging_mixin.py:109} INFO - 3
[2022-09-15 05:22:23,239] {taskinstance.py:1700} ERROR - Task failed with exception
Traceback (most recent call last):
  File "/home/airflow/.local/lib/python3.7/site-packages/airflow/models/taskinstance.py", line 1329, in _run_raw_task
    self._execute_task_with_callbacks(context)
  File "/home/airflow/.local/lib/python3.7/site-packages/airflow/models/taskinstance.py", line 1455, in _execute_task_with_callbacks
    result = self._execute_task(context, self.task)
  File "/home/airflow/.local/lib/python3.7/site-packages/airflow/models/taskinstance.py", line 1511, in _execute_task
    result = execute_callable(context=context)
  File "/home/airflow/.local/lib/python3.7/site-packages/airflow/operators/python.py", line 174, in execute
    return_value = self.execute_callable()
  File "/home/airflow/.local/lib/python3.7/site-packages/airflow/operators/python.py", line 185, in execute_callable
    return self.python_callable(*self.op_args, **self.op_kwargs)
  File "/opt/airflow/dags/FHV_ingest_19.py", line 25, in ingest_call
    outparq = pd.read_parquet(filePath)
  File "/home/airflow/.local/lib/python3.7/site-packages/pandas/io/parquet.py", line 500, in read_parquet
    **kwargs,
  File "/home/airflow/.local/lib/python3.7/site-packages/pandas/io/parquet.py", line 241, in read
    ).to_pandas(**to_pandas_kwargs)
  File "pyarrow/array.pxi", line 757, in pyarrow.lib._PandasConvertible.to_pandas
  File "pyarrow/table.pxi", line 1748, in pyarrow.lib.Table._to_pandas
  File "/home/airflow/.local/lib/python3.7/site-packages/pyarrow/pandas_compat.py", line 789, in table_to_blockmanager
    blocks = _table_to_blocks(options, table, categories, ext_columns_dtypes)
  File "/home/airflow/.local/lib/python3.7/site-packages/pyarrow/pandas_compat.py", line 1129, in _table_to_blocks
    list(extension_columns.keys()))
  File "pyarrow/table.pxi", line 1156, in pyarrow.lib.table_to_blocks
  File "pyarrow/error.pxi", line 99, in pyarrow.lib.check_status
pyarrow.lib.ArrowInvalid: Casting from timestamp[us] to timestamp[ns] would result in out of bounds timestamp: 33119051544000000
[2022-09-15 05:22:23,253] {taskinstance.py:1277} INFO - Marking task as FAILED. dag_id=FHVIngestionDag, task_id=ingest, execution_date=20190701T060000, start_date=20220915T052222, end_date=20220915T052223
[2022-09-15 05:22:23,323] {standard_task_runner.py:92} ERROR - Failed to execute job 159 for task ingest
Traceback (most recent call last):
  File "/home/airflow/.local/lib/python3.7/site-packages/airflow/task/task_runner/standard_task_runner.py", line 85, in _start_by_fork
    args.func(args, dag=self.dag)
  File "/home/airflow/.local/lib/python3.7/site-packages/airflow/cli/cli_parser.py", line 48, in command
    return func(*args, **kwargs)
  File "/home/airflow/.local/lib/python3.7/site-packages/airflow/utils/cli.py", line 92, in wrapper
    return f(*args, **kwargs)
  File "/home/airflow/.local/lib/python3.7/site-packages/airflow/cli/commands/task_command.py", line 298, in task_run
    _run_task_by_selected_method(args, dag, ti)
  File "/home/airflow/.local/lib/python3.7/site-packages/airflow/cli/commands/task_command.py", line 107, in _run_task_by_selected_method
    _run_raw_task(args, ti)
  File "/home/airflow/.local/lib/python3.7/site-packages/airflow/cli/commands/task_command.py", line 184, in _run_raw_task
    error_file=args.error_file,
  File "/home/airflow/.local/lib/python3.7/site-packages/airflow/utils/session.py", line 70, in wrapper
    return func(*args, session=session, **kwargs)
  File "/home/airflow/.local/lib/python3.7/site-packages/airflow/models/taskinstance.py", line 1329, in _run_raw_task
    self._execute_task_with_callbacks(context)
  File "/home/airflow/.local/lib/python3.7/site-packages/airflow/models/taskinstance.py", line 1455, in _execute_task_with_callbacks
    result = self._execute_task(context, self.task)
  File "/home/airflow/.local/lib/python3.7/site-packages/airflow/models/taskinstance.py", line 1511, in _execute_task
    result = execute_callable(context=context)
  File "/home/airflow/.local/lib/python3.7/site-packages/airflow/operators/python.py", line 174, in execute
    return_value = self.execute_callable()
  File "/home/airflow/.local/lib/python3.7/site-packages/airflow/operators/python.py", line 185, in execute_callable
    return self.python_callable(*self.op_args, **self.op_kwargs)
  File "/opt/airflow/dags/FHV_ingest_19.py", line 25, in ingest_call
    outparq = pd.read_parquet(filePath)
  File "/home/airflow/.local/lib/python3.7/site-packages/pandas/io/parquet.py", line 500, in read_parquet
    **kwargs,
  File "/home/airflow/.local/lib/python3.7/site-packages/pandas/io/parquet.py", line 241, in read
    ).to_pandas(**to_pandas_kwargs)
  File "pyarrow/array.pxi", line 757, in pyarrow.lib._PandasConvertible.to_pandas
  File "pyarrow/table.pxi", line 1748, in pyarrow.lib.Table._to_pandas
  File "/home/airflow/.local/lib/python3.7/site-packages/pyarrow/pandas_compat.py", line 789, in table_to_blockmanager
    blocks = _table_to_blocks(options, table, categories, ext_columns_dtypes)
  File "/home/airflow/.local/lib/python3.7/site-packages/pyarrow/pandas_compat.py", line 1129, in _table_to_blocks
    list(extension_columns.keys()))
  File "pyarrow/table.pxi", line 1156, in pyarrow.lib.table_to_blocks
  File "pyarrow/error.pxi", line 99, in pyarrow.lib.check_status
pyarrow.lib.ArrowInvalid: Casting from timestamp[us] to timestamp[ns] would result in out of bounds timestamp: 33119051544000000
[2022-09-15 05:22:23,384] {local_task_job.py:154} INFO - Task exited with return code 1
[2022-09-15 05:22:23,487] {local_task_job.py:264} INFO - 0 downstream tasks scheduled from follow-on schedule check
