[2022-09-16 06:17:06,451] {taskinstance.py:1032} INFO - Dependencies all met for <TaskInstance: LocalIngestionDag.ingest scheduled__2019-05-01T06:00:00+00:00 [queued]>
[2022-09-16 06:17:06,461] {taskinstance.py:1032} INFO - Dependencies all met for <TaskInstance: LocalIngestionDag.ingest scheduled__2019-05-01T06:00:00+00:00 [queued]>
[2022-09-16 06:17:06,462] {taskinstance.py:1238} INFO - 
--------------------------------------------------------------------------------
[2022-09-16 06:17:06,462] {taskinstance.py:1239} INFO - Starting attempt 1 of 1
[2022-09-16 06:17:06,462] {taskinstance.py:1240} INFO - 
--------------------------------------------------------------------------------
[2022-09-16 06:17:06,521] {taskinstance.py:1259} INFO - Executing <Task(PythonOperator): ingest> on 2019-05-01 06:00:00+00:00
[2022-09-16 06:17:06,526] {standard_task_runner.py:52} INFO - Started process 795 to run task
[2022-09-16 06:17:06,532] {standard_task_runner.py:76} INFO - Running: ['***', 'tasks', 'run', 'LocalIngestionDag', 'ingest', 'scheduled__2019-05-01T06:00:00+00:00', '--job-id', '194', '--raw', '--subdir', 'DAGS_FOLDER/ingest_data_dag.py', '--cfg-path', '/tmp/tmpnenukw2v', '--error-file', '/tmp/tmpu7wkfknx']
[2022-09-16 06:17:06,533] {standard_task_runner.py:77} INFO - Job 194: Subtask ingest
[2022-09-16 06:17:06,613] {logging_mixin.py:109} INFO - Running <TaskInstance: LocalIngestionDag.ingest scheduled__2019-05-01T06:00:00+00:00 [running]> on host 1bec96cb997e
[2022-09-16 06:17:06,691] {logging_mixin.py:109} WARNING - /home/***/.local/lib/python3.7/site-packages/***/utils/context.py:152 AirflowContextDeprecationWarning: Accessing 'execution_date' from the template is deprecated and will be removed in a future version. Please use 'data_interval_start' or 'logical_date' instead.
[2022-09-16 06:17:06,748] {taskinstance.py:1426} INFO - Exporting the following env vars:
AIRFLOW_CTX_DAG_OWNER=***
AIRFLOW_CTX_DAG_ID=LocalIngestionDag
AIRFLOW_CTX_TASK_ID=ingest
AIRFLOW_CTX_EXECUTION_DATE=2019-05-01T06:00:00+00:00
AIRFLOW_CTX_DAG_RUN_ID=scheduled__2019-05-01T06:00:00+00:00
[2022-09-16 06:17:06,750] {logging_mixin.py:109} INFO - root   root   pgdatabase   5432   ny_taxi   yellow_taxi_2019_05   /opt/***/output_2019-05.parquet
[2022-09-16 06:17:10,333] {logging_mixin.py:109} INFO - Finally
[2022-09-16 06:17:10,334] {logging_mixin.py:109} INFO - 1
[2022-09-16 06:17:27,707] {base_job.py:230} ERROR - LocalTaskJob heartbeat got an exception
Traceback (most recent call last):
  File "/home/airflow/.local/lib/python3.7/site-packages/sqlalchemy/engine/base.py", line 2336, in _wrap_pool_connect
    return fn()
  File "/home/airflow/.local/lib/python3.7/site-packages/sqlalchemy/pool/base.py", line 364, in connect
    return _ConnectionFairy._checkout(self)
  File "/home/airflow/.local/lib/python3.7/site-packages/sqlalchemy/pool/base.py", line 778, in _checkout
    fairy = _ConnectionRecord.checkout(pool)
  File "/home/airflow/.local/lib/python3.7/site-packages/sqlalchemy/pool/base.py", line 495, in checkout
    rec = pool._do_get()
  File "/home/airflow/.local/lib/python3.7/site-packages/sqlalchemy/pool/impl.py", line 241, in _do_get
    return self._create_connection()
  File "/home/airflow/.local/lib/python3.7/site-packages/sqlalchemy/pool/base.py", line 309, in _create_connection
    return _ConnectionRecord(self)
  File "/home/airflow/.local/lib/python3.7/site-packages/sqlalchemy/pool/base.py", line 440, in __init__
    self.__connect(first_connect_check=True)
  File "/home/airflow/.local/lib/python3.7/site-packages/sqlalchemy/pool/base.py", line 661, in __connect
    pool.logger.debug("Error on connect(): %s", e)
  File "/home/airflow/.local/lib/python3.7/site-packages/sqlalchemy/util/langhelpers.py", line 70, in __exit__
    with_traceback=exc_tb,
  File "/home/airflow/.local/lib/python3.7/site-packages/sqlalchemy/util/compat.py", line 182, in raise_
    raise exception
  File "/home/airflow/.local/lib/python3.7/site-packages/sqlalchemy/pool/base.py", line 656, in __connect
    connection = pool._invoke_creator(self)
  File "/home/airflow/.local/lib/python3.7/site-packages/sqlalchemy/engine/strategies.py", line 114, in connect
    return dialect.connect(*cargs, **cparams)
  File "/home/airflow/.local/lib/python3.7/site-packages/sqlalchemy/engine/default.py", line 508, in connect
    return self.dbapi.connect(*cargs, **cparams)
  File "/home/airflow/.local/lib/python3.7/site-packages/psycopg2/__init__.py", line 122, in connect
    conn = _connect(dsn, connection_factory=connection_factory, **kwasync)
psycopg2.OperationalError: could not translate host name "postgres" to address: Temporary failure in name resolution


The above exception was the direct cause of the following exception:

Traceback (most recent call last):
  File "/home/airflow/.local/lib/python3.7/site-packages/airflow/jobs/base_job.py", line 202, in heartbeat
    session.merge(self)
  File "/home/airflow/.local/lib/python3.7/site-packages/sqlalchemy/orm/session.py", line 2171, in merge
    _resolve_conflict_map=_resolve_conflict_map,
  File "/home/airflow/.local/lib/python3.7/site-packages/sqlalchemy/orm/session.py", line 2244, in _merge
    merged = self.query(mapper.class_).get(key[1])
  File "/home/airflow/.local/lib/python3.7/site-packages/sqlalchemy/orm/query.py", line 1018, in get
    return self._get_impl(ident, loading.load_on_pk_identity)
  File "/home/airflow/.local/lib/python3.7/site-packages/sqlalchemy/orm/query.py", line 1135, in _get_impl
    return db_load_fn(self, primary_key_identity)
  File "/home/airflow/.local/lib/python3.7/site-packages/sqlalchemy/orm/loading.py", line 286, in load_on_pk_identity
    return q.one()
  File "/home/airflow/.local/lib/python3.7/site-packages/sqlalchemy/orm/query.py", line 3490, in one
    ret = self.one_or_none()
  File "/home/airflow/.local/lib/python3.7/site-packages/sqlalchemy/orm/query.py", line 3459, in one_or_none
    ret = list(self)
  File "/home/airflow/.local/lib/python3.7/site-packages/sqlalchemy/orm/query.py", line 3535, in __iter__
    return self._execute_and_instances(context)
  File "/home/airflow/.local/lib/python3.7/site-packages/sqlalchemy/orm/query.py", line 3557, in _execute_and_instances
    querycontext, self._connection_from_session, close_with_result=True
  File "/home/airflow/.local/lib/python3.7/site-packages/sqlalchemy/orm/query.py", line 3572, in _get_bind_args
    mapper=self._bind_mapper(), clause=querycontext.statement, **kw
  File "/home/airflow/.local/lib/python3.7/site-packages/sqlalchemy/orm/query.py", line 3550, in _connection_from_session
    conn = self.session.connection(**kw)
  File "/home/airflow/.local/lib/python3.7/site-packages/sqlalchemy/orm/session.py", line 1145, in connection
    execution_options=execution_options,
  File "/home/airflow/.local/lib/python3.7/site-packages/sqlalchemy/orm/session.py", line 1151, in _connection_for_bind
    engine, execution_options
  File "/home/airflow/.local/lib/python3.7/site-packages/sqlalchemy/orm/session.py", line 433, in _connection_for_bind
    conn = bind._contextual_connect()
  File "/home/airflow/.local/lib/python3.7/site-packages/sqlalchemy/engine/base.py", line 2302, in _contextual_connect
    self._wrap_pool_connect(self.pool.connect, None),
  File "/home/airflow/.local/lib/python3.7/site-packages/sqlalchemy/engine/base.py", line 2340, in _wrap_pool_connect
    e, dialect, self
  File "/home/airflow/.local/lib/python3.7/site-packages/sqlalchemy/engine/base.py", line 1584, in _handle_dbapi_exception_noconnection
    sqlalchemy_exception, with_traceback=exc_info[2], from_=e
  File "/home/airflow/.local/lib/python3.7/site-packages/sqlalchemy/util/compat.py", line 182, in raise_
    raise exception
  File "/home/airflow/.local/lib/python3.7/site-packages/sqlalchemy/engine/base.py", line 2336, in _wrap_pool_connect
    return fn()
  File "/home/airflow/.local/lib/python3.7/site-packages/sqlalchemy/pool/base.py", line 364, in connect
    return _ConnectionFairy._checkout(self)
  File "/home/airflow/.local/lib/python3.7/site-packages/sqlalchemy/pool/base.py", line 778, in _checkout
    fairy = _ConnectionRecord.checkout(pool)
  File "/home/airflow/.local/lib/python3.7/site-packages/sqlalchemy/pool/base.py", line 495, in checkout
    rec = pool._do_get()
  File "/home/airflow/.local/lib/python3.7/site-packages/sqlalchemy/pool/impl.py", line 241, in _do_get
    return self._create_connection()
  File "/home/airflow/.local/lib/python3.7/site-packages/sqlalchemy/pool/base.py", line 309, in _create_connection
    return _ConnectionRecord(self)
  File "/home/airflow/.local/lib/python3.7/site-packages/sqlalchemy/pool/base.py", line 440, in __init__
    self.__connect(first_connect_check=True)
  File "/home/airflow/.local/lib/python3.7/site-packages/sqlalchemy/pool/base.py", line 661, in __connect
    pool.logger.debug("Error on connect(): %s", e)
  File "/home/airflow/.local/lib/python3.7/site-packages/sqlalchemy/util/langhelpers.py", line 70, in __exit__
    with_traceback=exc_tb,
  File "/home/airflow/.local/lib/python3.7/site-packages/sqlalchemy/util/compat.py", line 182, in raise_
    raise exception
  File "/home/airflow/.local/lib/python3.7/site-packages/sqlalchemy/pool/base.py", line 656, in __connect
    connection = pool._invoke_creator(self)
  File "/home/airflow/.local/lib/python3.7/site-packages/sqlalchemy/engine/strategies.py", line 114, in connect
    return dialect.connect(*cargs, **cparams)
  File "/home/airflow/.local/lib/python3.7/site-packages/sqlalchemy/engine/default.py", line 508, in connect
    return self.dbapi.connect(*cargs, **cparams)
  File "/home/airflow/.local/lib/python3.7/site-packages/psycopg2/__init__.py", line 122, in connect
    conn = _connect(dsn, connection_factory=connection_factory, **kwasync)
sqlalchemy.exc.OperationalError: (psycopg2.OperationalError) could not translate host name "postgres" to address: Temporary failure in name resolution

(Background on this error at: http://sqlalche.me/e/13/e3q8)
[2022-09-16 06:18:36,174] {logging_mixin.py:109} INFO - 2
[2022-09-16 06:18:35,496] {base_job.py:230} ERROR - LocalTaskJob heartbeat got an exception
Traceback (most recent call last):
  File "/home/airflow/.local/lib/python3.7/site-packages/sqlalchemy/engine/base.py", line 2336, in _wrap_pool_connect
    return fn()
  File "/home/airflow/.local/lib/python3.7/site-packages/sqlalchemy/pool/base.py", line 364, in connect
    return _ConnectionFairy._checkout(self)
  File "/home/airflow/.local/lib/python3.7/site-packages/sqlalchemy/pool/base.py", line 778, in _checkout
    fairy = _ConnectionRecord.checkout(pool)
  File "/home/airflow/.local/lib/python3.7/site-packages/sqlalchemy/pool/base.py", line 495, in checkout
    rec = pool._do_get()
  File "/home/airflow/.local/lib/python3.7/site-packages/sqlalchemy/pool/impl.py", line 241, in _do_get
    return self._create_connection()
  File "/home/airflow/.local/lib/python3.7/site-packages/sqlalchemy/pool/base.py", line 309, in _create_connection
    return _ConnectionRecord(self)
  File "/home/airflow/.local/lib/python3.7/site-packages/sqlalchemy/pool/base.py", line 440, in __init__
    self.__connect(first_connect_check=True)
  File "/home/airflow/.local/lib/python3.7/site-packages/sqlalchemy/pool/base.py", line 661, in __connect
    pool.logger.debug("Error on connect(): %s", e)
  File "/home/airflow/.local/lib/python3.7/site-packages/sqlalchemy/util/langhelpers.py", line 70, in __exit__
    with_traceback=exc_tb,
  File "/home/airflow/.local/lib/python3.7/site-packages/sqlalchemy/util/compat.py", line 182, in raise_
    raise exception
  File "/home/airflow/.local/lib/python3.7/site-packages/sqlalchemy/pool/base.py", line 656, in __connect
    connection = pool._invoke_creator(self)
  File "/home/airflow/.local/lib/python3.7/site-packages/sqlalchemy/engine/strategies.py", line 114, in connect
    return dialect.connect(*cargs, **cparams)
  File "/home/airflow/.local/lib/python3.7/site-packages/sqlalchemy/engine/default.py", line 508, in connect
    return self.dbapi.connect(*cargs, **cparams)
  File "/home/airflow/.local/lib/python3.7/site-packages/psycopg2/__init__.py", line 122, in connect
    conn = _connect(dsn, connection_factory=connection_factory, **kwasync)
psycopg2.OperationalError: could not translate host name "postgres" to address: Temporary failure in name resolution


The above exception was the direct cause of the following exception:

Traceback (most recent call last):
  File "/home/airflow/.local/lib/python3.7/site-packages/airflow/jobs/base_job.py", line 202, in heartbeat
    session.merge(self)
  File "/home/airflow/.local/lib/python3.7/site-packages/sqlalchemy/orm/session.py", line 2171, in merge
    _resolve_conflict_map=_resolve_conflict_map,
  File "/home/airflow/.local/lib/python3.7/site-packages/sqlalchemy/orm/session.py", line 2244, in _merge
    merged = self.query(mapper.class_).get(key[1])
  File "/home/airflow/.local/lib/python3.7/site-packages/sqlalchemy/orm/query.py", line 1018, in get
    return self._get_impl(ident, loading.load_on_pk_identity)
  File "/home/airflow/.local/lib/python3.7/site-packages/sqlalchemy/orm/query.py", line 1135, in _get_impl
    return db_load_fn(self, primary_key_identity)
  File "/home/airflow/.local/lib/python3.7/site-packages/sqlalchemy/orm/loading.py", line 286, in load_on_pk_identity
    return q.one()
  File "/home/airflow/.local/lib/python3.7/site-packages/sqlalchemy/orm/query.py", line 3490, in one
    ret = self.one_or_none()
  File "/home/airflow/.local/lib/python3.7/site-packages/sqlalchemy/orm/query.py", line 3459, in one_or_none
    ret = list(self)
  File "/home/airflow/.local/lib/python3.7/site-packages/sqlalchemy/orm/query.py", line 3535, in __iter__
    return self._execute_and_instances(context)
  File "/home/airflow/.local/lib/python3.7/site-packages/sqlalchemy/orm/query.py", line 3557, in _execute_and_instances
    querycontext, self._connection_from_session, close_with_result=True
  File "/home/airflow/.local/lib/python3.7/site-packages/sqlalchemy/orm/query.py", line 3572, in _get_bind_args
    mapper=self._bind_mapper(), clause=querycontext.statement, **kw
  File "/home/airflow/.local/lib/python3.7/site-packages/sqlalchemy/orm/query.py", line 3550, in _connection_from_session
    conn = self.session.connection(**kw)
  File "/home/airflow/.local/lib/python3.7/site-packages/sqlalchemy/orm/session.py", line 1145, in connection
    execution_options=execution_options,
  File "/home/airflow/.local/lib/python3.7/site-packages/sqlalchemy/orm/session.py", line 1151, in _connection_for_bind
    engine, execution_options
  File "/home/airflow/.local/lib/python3.7/site-packages/sqlalchemy/orm/session.py", line 433, in _connection_for_bind
    conn = bind._contextual_connect()
  File "/home/airflow/.local/lib/python3.7/site-packages/sqlalchemy/engine/base.py", line 2302, in _contextual_connect
    self._wrap_pool_connect(self.pool.connect, None),
  File "/home/airflow/.local/lib/python3.7/site-packages/sqlalchemy/engine/base.py", line 2340, in _wrap_pool_connect
    e, dialect, self
  File "/home/airflow/.local/lib/python3.7/site-packages/sqlalchemy/engine/base.py", line 1584, in _handle_dbapi_exception_noconnection
    sqlalchemy_exception, with_traceback=exc_info[2], from_=e
  File "/home/airflow/.local/lib/python3.7/site-packages/sqlalchemy/util/compat.py", line 182, in raise_
    raise exception
  File "/home/airflow/.local/lib/python3.7/site-packages/sqlalchemy/engine/base.py", line 2336, in _wrap_pool_connect
    return fn()
  File "/home/airflow/.local/lib/python3.7/site-packages/sqlalchemy/pool/base.py", line 364, in connect
    return _ConnectionFairy._checkout(self)
  File "/home/airflow/.local/lib/python3.7/site-packages/sqlalchemy/pool/base.py", line 778, in _checkout
    fairy = _ConnectionRecord.checkout(pool)
  File "/home/airflow/.local/lib/python3.7/site-packages/sqlalchemy/pool/base.py", line 495, in checkout
    rec = pool._do_get()
  File "/home/airflow/.local/lib/python3.7/site-packages/sqlalchemy/pool/impl.py", line 241, in _do_get
    return self._create_connection()
  File "/home/airflow/.local/lib/python3.7/site-packages/sqlalchemy/pool/base.py", line 309, in _create_connection
    return _ConnectionRecord(self)
  File "/home/airflow/.local/lib/python3.7/site-packages/sqlalchemy/pool/base.py", line 440, in __init__
    self.__connect(first_connect_check=True)
  File "/home/airflow/.local/lib/python3.7/site-packages/sqlalchemy/pool/base.py", line 661, in __connect
    pool.logger.debug("Error on connect(): %s", e)
  File "/home/airflow/.local/lib/python3.7/site-packages/sqlalchemy/util/langhelpers.py", line 70, in __exit__
    with_traceback=exc_tb,
  File "/home/airflow/.local/lib/python3.7/site-packages/sqlalchemy/util/compat.py", line 182, in raise_
    raise exception
  File "/home/airflow/.local/lib/python3.7/site-packages/sqlalchemy/pool/base.py", line 656, in __connect
    connection = pool._invoke_creator(self)
  File "/home/airflow/.local/lib/python3.7/site-packages/sqlalchemy/engine/strategies.py", line 114, in connect
    return dialect.connect(*cargs, **cparams)
  File "/home/airflow/.local/lib/python3.7/site-packages/sqlalchemy/engine/default.py", line 508, in connect
    return self.dbapi.connect(*cargs, **cparams)
  File "/home/airflow/.local/lib/python3.7/site-packages/psycopg2/__init__.py", line 122, in connect
    conn = _connect(dsn, connection_factory=connection_factory, **kwasync)
sqlalchemy.exc.OperationalError: (psycopg2.OperationalError) could not translate host name "postgres" to address: Temporary failure in name resolution

(Background on this error at: http://sqlalche.me/e/13/e3q8)
[2022-09-16 06:18:49,165] {taskinstance.py:1700} ERROR - Task failed with exception
Traceback (most recent call last):
  File "/home/airflow/.local/lib/python3.7/site-packages/sqlalchemy/engine/base.py", line 2336, in _wrap_pool_connect
    return fn()
  File "/home/airflow/.local/lib/python3.7/site-packages/sqlalchemy/pool/base.py", line 364, in connect
    return _ConnectionFairy._checkout(self)
  File "/home/airflow/.local/lib/python3.7/site-packages/sqlalchemy/pool/base.py", line 778, in _checkout
    fairy = _ConnectionRecord.checkout(pool)
  File "/home/airflow/.local/lib/python3.7/site-packages/sqlalchemy/pool/base.py", line 495, in checkout
    rec = pool._do_get()
  File "/home/airflow/.local/lib/python3.7/site-packages/sqlalchemy/pool/impl.py", line 140, in _do_get
    self._dec_overflow()
  File "/home/airflow/.local/lib/python3.7/site-packages/sqlalchemy/util/langhelpers.py", line 70, in __exit__
    with_traceback=exc_tb,
  File "/home/airflow/.local/lib/python3.7/site-packages/sqlalchemy/util/compat.py", line 182, in raise_
    raise exception
  File "/home/airflow/.local/lib/python3.7/site-packages/sqlalchemy/pool/impl.py", line 137, in _do_get
    return self._create_connection()
  File "/home/airflow/.local/lib/python3.7/site-packages/sqlalchemy/pool/base.py", line 309, in _create_connection
    return _ConnectionRecord(self)
  File "/home/airflow/.local/lib/python3.7/site-packages/sqlalchemy/pool/base.py", line 440, in __init__
    self.__connect(first_connect_check=True)
  File "/home/airflow/.local/lib/python3.7/site-packages/sqlalchemy/pool/base.py", line 661, in __connect
    pool.logger.debug("Error on connect(): %s", e)
  File "/home/airflow/.local/lib/python3.7/site-packages/sqlalchemy/util/langhelpers.py", line 70, in __exit__
    with_traceback=exc_tb,
  File "/home/airflow/.local/lib/python3.7/site-packages/sqlalchemy/util/compat.py", line 182, in raise_
    raise exception
  File "/home/airflow/.local/lib/python3.7/site-packages/sqlalchemy/pool/base.py", line 656, in __connect
    connection = pool._invoke_creator(self)
  File "/home/airflow/.local/lib/python3.7/site-packages/sqlalchemy/engine/strategies.py", line 114, in connect
    return dialect.connect(*cargs, **cparams)
  File "/home/airflow/.local/lib/python3.7/site-packages/sqlalchemy/engine/default.py", line 508, in connect
    return self.dbapi.connect(*cargs, **cparams)
  File "/home/airflow/.local/lib/python3.7/site-packages/psycopg2/__init__.py", line 122, in connect
    conn = _connect(dsn, connection_factory=connection_factory, **kwasync)
psycopg2.OperationalError: could not translate host name "pgdatabase" to address: Temporary failure in name resolution


The above exception was the direct cause of the following exception:

Traceback (most recent call last):
  File "/home/airflow/.local/lib/python3.7/site-packages/airflow/models/taskinstance.py", line 1329, in _run_raw_task
    self._execute_task_with_callbacks(context)
  File "/home/airflow/.local/lib/python3.7/site-packages/airflow/models/taskinstance.py", line 1455, in _execute_task_with_callbacks
    result = self._execute_task(context, self.task)
  File "/home/airflow/.local/lib/python3.7/site-packages/airflow/models/taskinstance.py", line 1511, in _execute_task
    result = execute_callable(context=context)
  File "/home/airflow/.local/lib/python3.7/site-packages/airflow/operators/python.py", line 174, in execute
    return_value = self.execute_callable()
  File "/home/airflow/.local/lib/python3.7/site-packages/airflow/operators/python.py", line 185, in execute_callable
    return self.python_callable(*self.op_args, **self.op_kwargs)
  File "/opt/airflow/dags/ingest_data_dag.py", line 30, in ingest_call
    outparq.to_sql(name= table_name, con=engine, if_exists='replace',chunksize=10000)
  File "/home/airflow/.local/lib/python3.7/site-packages/pandas/core/generic.py", line 2882, in to_sql
    method=method,
  File "/home/airflow/.local/lib/python3.7/site-packages/pandas/io/sql.py", line 728, in to_sql
    **engine_kwargs,
  File "/home/airflow/.local/lib/python3.7/site-packages/pandas/io/sql.py", line 1758, in to_sql
    dtype=dtype,
  File "/home/airflow/.local/lib/python3.7/site-packages/pandas/io/sql.py", line 1650, in prep_table
    table.create()
  File "/home/airflow/.local/lib/python3.7/site-packages/pandas/io/sql.py", line 856, in create
    if self.exists():
  File "/home/airflow/.local/lib/python3.7/site-packages/pandas/io/sql.py", line 840, in exists
    return self.pd_sql.has_table(self.name, self.schema)
  File "/home/airflow/.local/lib/python3.7/site-packages/pandas/io/sql.py", line 1787, in has_table
    self.connectable.dialect.has_table, name, schema or self.meta.schema
  File "/home/airflow/.local/lib/python3.7/site-packages/sqlalchemy/engine/base.py", line 2211, in run_callable
    with self._contextual_connect() as conn:
  File "/home/airflow/.local/lib/python3.7/site-packages/sqlalchemy/engine/base.py", line 2302, in _contextual_connect
    self._wrap_pool_connect(self.pool.connect, None),
  File "/home/airflow/.local/lib/python3.7/site-packages/sqlalchemy/engine/base.py", line 2340, in _wrap_pool_connect
    e, dialect, self
  File "/home/airflow/.local/lib/python3.7/site-packages/sqlalchemy/engine/base.py", line 1584, in _handle_dbapi_exception_noconnection
    sqlalchemy_exception, with_traceback=exc_info[2], from_=e
  File "/home/airflow/.local/lib/python3.7/site-packages/sqlalchemy/util/compat.py", line 182, in raise_
    raise exception
  File "/home/airflow/.local/lib/python3.7/site-packages/sqlalchemy/engine/base.py", line 2336, in _wrap_pool_connect
    return fn()
  File "/home/airflow/.local/lib/python3.7/site-packages/sqlalchemy/pool/base.py", line 364, in connect
    return _ConnectionFairy._checkout(self)
  File "/home/airflow/.local/lib/python3.7/site-packages/sqlalchemy/pool/base.py", line 778, in _checkout
    fairy = _ConnectionRecord.checkout(pool)
  File "/home/airflow/.local/lib/python3.7/site-packages/sqlalchemy/pool/base.py", line 495, in checkout
    rec = pool._do_get()
  File "/home/airflow/.local/lib/python3.7/site-packages/sqlalchemy/pool/impl.py", line 140, in _do_get
    self._dec_overflow()
  File "/home/airflow/.local/lib/python3.7/site-packages/sqlalchemy/util/langhelpers.py", line 70, in __exit__
    with_traceback=exc_tb,
  File "/home/airflow/.local/lib/python3.7/site-packages/sqlalchemy/util/compat.py", line 182, in raise_
    raise exception
  File "/home/airflow/.local/lib/python3.7/site-packages/sqlalchemy/pool/impl.py", line 137, in _do_get
    return self._create_connection()
  File "/home/airflow/.local/lib/python3.7/site-packages/sqlalchemy/pool/base.py", line 309, in _create_connection
    return _ConnectionRecord(self)
  File "/home/airflow/.local/lib/python3.7/site-packages/sqlalchemy/pool/base.py", line 440, in __init__
    self.__connect(first_connect_check=True)
  File "/home/airflow/.local/lib/python3.7/site-packages/sqlalchemy/pool/base.py", line 661, in __connect
    pool.logger.debug("Error on connect(): %s", e)
  File "/home/airflow/.local/lib/python3.7/site-packages/sqlalchemy/util/langhelpers.py", line 70, in __exit__
    with_traceback=exc_tb,
  File "/home/airflow/.local/lib/python3.7/site-packages/sqlalchemy/util/compat.py", line 182, in raise_
    raise exception
  File "/home/airflow/.local/lib/python3.7/site-packages/sqlalchemy/pool/base.py", line 656, in __connect
    connection = pool._invoke_creator(self)
  File "/home/airflow/.local/lib/python3.7/site-packages/sqlalchemy/engine/strategies.py", line 114, in connect
    return dialect.connect(*cargs, **cparams)
  File "/home/airflow/.local/lib/python3.7/site-packages/sqlalchemy/engine/default.py", line 508, in connect
    return self.dbapi.connect(*cargs, **cparams)
  File "/home/airflow/.local/lib/python3.7/site-packages/psycopg2/__init__.py", line 122, in connect
    conn = _connect(dsn, connection_factory=connection_factory, **kwasync)
sqlalchemy.exc.OperationalError: (psycopg2.OperationalError) could not translate host name "pgdatabase" to address: Temporary failure in name resolution

(Background on this error at: http://sqlalche.me/e/13/e3q8)
[2022-09-16 06:18:52,073] {taskinstance.py:1277} INFO - Marking task as FAILED. dag_id=LocalIngestionDag, task_id=ingest, execution_date=20190501T060000, start_date=20220916T061706, end_date=20220916T061852
[2022-09-16 06:18:53,349] {local_task_job.py:212} WARNING - State of this instance has been externally set to failed. Terminating instance.
[2022-09-16 06:18:53,353] {process_utils.py:124} INFO - Sending Signals.SIGTERM to group 795. PIDs of all processes in the group: [795]
[2022-09-16 06:18:53,353] {process_utils.py:75} INFO - Sending the signal Signals.SIGTERM to group 795
[2022-09-16 06:18:53,361] {taskinstance.py:1408} ERROR - Received SIGTERM. Terminating subprocesses.
[2022-09-16 06:18:53,361] {logging_mixin.py:109} WARNING - --- Logging error ---
[2022-09-16 06:18:54,349] {logging_mixin.py:109} WARNING - Traceback (most recent call last):
[2022-09-16 06:18:54,350] {logging_mixin.py:109} WARNING -   File "/home/***/.local/lib/python3.7/site-packages/sqlalchemy/engine/base.py", line 2336, in _wrap_pool_connect
    return fn()
[2022-09-16 06:18:54,351] {logging_mixin.py:109} WARNING -   File "/home/***/.local/lib/python3.7/site-packages/sqlalchemy/pool/base.py", line 364, in connect
    return _ConnectionFairy._checkout(self)
[2022-09-16 06:18:54,352] {logging_mixin.py:109} WARNING -   File "/home/***/.local/lib/python3.7/site-packages/sqlalchemy/pool/base.py", line 778, in _checkout
    fairy = _ConnectionRecord.checkout(pool)
[2022-09-16 06:18:54,353] {logging_mixin.py:109} WARNING -   File "/home/***/.local/lib/python3.7/site-packages/sqlalchemy/pool/base.py", line 495, in checkout
    rec = pool._do_get()
[2022-09-16 06:18:54,354] {logging_mixin.py:109} WARNING -   File "/home/***/.local/lib/python3.7/site-packages/sqlalchemy/pool/impl.py", line 140, in _do_get
    self._dec_overflow()
[2022-09-16 06:18:54,354] {logging_mixin.py:109} WARNING -   File "/home/***/.local/lib/python3.7/site-packages/sqlalchemy/util/langhelpers.py", line 70, in __exit__
    with_traceback=exc_tb,
[2022-09-16 06:18:54,355] {logging_mixin.py:109} WARNING -   File "/home/***/.local/lib/python3.7/site-packages/sqlalchemy/util/compat.py", line 182, in raise_
    raise exception
[2022-09-16 06:18:54,356] {logging_mixin.py:109} WARNING -   File "/home/***/.local/lib/python3.7/site-packages/sqlalchemy/pool/impl.py", line 137, in _do_get
    return self._create_connection()
[2022-09-16 06:18:54,357] {logging_mixin.py:109} WARNING -   File "/home/***/.local/lib/python3.7/site-packages/sqlalchemy/pool/base.py", line 309, in _create_connection
    return _ConnectionRecord(self)
[2022-09-16 06:18:54,358] {logging_mixin.py:109} WARNING -   File "/home/***/.local/lib/python3.7/site-packages/sqlalchemy/pool/base.py", line 440, in __init__
    self.__connect(first_connect_check=True)
[2022-09-16 06:18:54,359] {logging_mixin.py:109} WARNING -   File "/home/***/.local/lib/python3.7/site-packages/sqlalchemy/pool/base.py", line 661, in __connect
    pool.logger.debug("Error on connect(): %s", e)
[2022-09-16 06:18:54,360] {logging_mixin.py:109} WARNING -   File "/home/***/.local/lib/python3.7/site-packages/sqlalchemy/util/langhelpers.py", line 70, in __exit__
    with_traceback=exc_tb,
[2022-09-16 06:18:54,361] {logging_mixin.py:109} WARNING -   File "/home/***/.local/lib/python3.7/site-packages/sqlalchemy/util/compat.py", line 182, in raise_
    raise exception
[2022-09-16 06:18:54,362] {logging_mixin.py:109} WARNING -   File "/home/***/.local/lib/python3.7/site-packages/sqlalchemy/pool/base.py", line 656, in __connect
    connection = pool._invoke_creator(self)
[2022-09-16 06:18:54,363] {logging_mixin.py:109} WARNING -   File "/home/***/.local/lib/python3.7/site-packages/sqlalchemy/engine/strategies.py", line 114, in connect
    return dialect.connect(*cargs, **cparams)
[2022-09-16 06:18:54,363] {logging_mixin.py:109} WARNING -   File "/home/***/.local/lib/python3.7/site-packages/sqlalchemy/engine/default.py", line 508, in connect
    return self.dbapi.connect(*cargs, **cparams)
[2022-09-16 06:18:54,364] {logging_mixin.py:109} WARNING -   File "/home/***/.local/lib/python3.7/site-packages/psycopg2/__init__.py", line 122, in connect
    conn = _connect(dsn, connection_factory=connection_factory, **kwasync)
[2022-09-16 06:18:54,365] {logging_mixin.py:109} WARNING - psycopg2.OperationalError: could not translate host name "pgdatabase" to address: Temporary failure in name resolution
[2022-09-16 06:18:54,366] {logging_mixin.py:109} WARNING - 
The above exception was the direct cause of the following exception:
[2022-09-16 06:18:54,367] {logging_mixin.py:109} WARNING - Traceback (most recent call last):
[2022-09-16 06:18:54,368] {logging_mixin.py:109} WARNING -   File "/home/***/.local/lib/python3.7/site-packages/***/task/task_runner/standard_task_runner.py", line 85, in _start_by_fork
    args.func(args, dag=self.dag)
[2022-09-16 06:18:54,369] {logging_mixin.py:109} WARNING -   File "/home/***/.local/lib/python3.7/site-packages/***/cli/cli_parser.py", line 48, in command
    return func(*args, **kwargs)
[2022-09-16 06:18:54,370] {logging_mixin.py:109} WARNING -   File "/home/***/.local/lib/python3.7/site-packages/***/utils/cli.py", line 92, in wrapper
    return f(*args, **kwargs)
[2022-09-16 06:18:54,371] {logging_mixin.py:109} WARNING -   File "/home/***/.local/lib/python3.7/site-packages/***/cli/commands/task_command.py", line 298, in task_run
    _run_task_by_selected_method(args, dag, ti)
[2022-09-16 06:18:54,371] {logging_mixin.py:109} WARNING -   File "/home/***/.local/lib/python3.7/site-packages/***/cli/commands/task_command.py", line 107, in _run_task_by_selected_method
    _run_raw_task(args, ti)
[2022-09-16 06:18:54,372] {logging_mixin.py:109} WARNING -   File "/home/***/.local/lib/python3.7/site-packages/***/cli/commands/task_command.py", line 184, in _run_raw_task
    error_file=args.error_file,
[2022-09-16 06:18:54,373] {logging_mixin.py:109} WARNING -   File "/home/***/.local/lib/python3.7/site-packages/***/utils/session.py", line 70, in wrapper
    return func(*args, session=session, **kwargs)
[2022-09-16 06:18:54,374] {logging_mixin.py:109} WARNING -   File "/home/***/.local/lib/python3.7/site-packages/***/models/taskinstance.py", line 1329, in _run_raw_task
    self._execute_task_with_callbacks(context)
[2022-09-16 06:18:54,375] {logging_mixin.py:109} WARNING -   File "/home/***/.local/lib/python3.7/site-packages/***/models/taskinstance.py", line 1455, in _execute_task_with_callbacks
    result = self._execute_task(context, self.task)
[2022-09-16 06:18:54,376] {logging_mixin.py:109} WARNING -   File "/home/***/.local/lib/python3.7/site-packages/***/models/taskinstance.py", line 1511, in _execute_task
    result = execute_callable(context=context)
[2022-09-16 06:18:54,377] {logging_mixin.py:109} WARNING -   File "/home/***/.local/lib/python3.7/site-packages/***/operators/python.py", line 174, in execute
    return_value = self.execute_callable()
[2022-09-16 06:18:54,378] {logging_mixin.py:109} WARNING -   File "/home/***/.local/lib/python3.7/site-packages/***/operators/python.py", line 185, in execute_callable
    return self.python_callable(*self.op_args, **self.op_kwargs)
[2022-09-16 06:18:54,378] {logging_mixin.py:109} WARNING -   File "/opt/***/dags/ingest_data_dag.py", line 30, in ingest_call
    outparq.to_sql(name= table_name, con=engine, if_exists='replace',chunksize=10000)
[2022-09-16 06:18:54,379] {logging_mixin.py:109} WARNING -   File "/home/***/.local/lib/python3.7/site-packages/pandas/core/generic.py", line 2882, in to_sql
    method=method,
[2022-09-16 06:18:54,380] {logging_mixin.py:109} WARNING -   File "/home/***/.local/lib/python3.7/site-packages/pandas/io/sql.py", line 728, in to_sql
    **engine_kwargs,
[2022-09-16 06:18:54,381] {logging_mixin.py:109} WARNING -   File "/home/***/.local/lib/python3.7/site-packages/pandas/io/sql.py", line 1758, in to_sql
    dtype=dtype,
[2022-09-16 06:18:54,382] {logging_mixin.py:109} WARNING -   File "/home/***/.local/lib/python3.7/site-packages/pandas/io/sql.py", line 1650, in prep_table
    table.create()
[2022-09-16 06:18:54,383] {logging_mixin.py:109} WARNING -   File "/home/***/.local/lib/python3.7/site-packages/pandas/io/sql.py", line 856, in create
    if self.exists():
[2022-09-16 06:18:54,383] {logging_mixin.py:109} WARNING -   File "/home/***/.local/lib/python3.7/site-packages/pandas/io/sql.py", line 840, in exists
    return self.pd_sql.has_table(self.name, self.schema)
[2022-09-16 06:18:54,384] {logging_mixin.py:109} WARNING -   File "/home/***/.local/lib/python3.7/site-packages/pandas/io/sql.py", line 1787, in has_table
    self.connectable.dialect.has_table, name, schema or self.meta.schema
[2022-09-16 06:18:54,385] {logging_mixin.py:109} WARNING -   File "/home/***/.local/lib/python3.7/site-packages/sqlalchemy/engine/base.py", line 2211, in run_callable
    with self._contextual_connect() as conn:
[2022-09-16 06:18:54,386] {logging_mixin.py:109} WARNING -   File "/home/***/.local/lib/python3.7/site-packages/sqlalchemy/engine/base.py", line 2302, in _contextual_connect
    self._wrap_pool_connect(self.pool.connect, None),
[2022-09-16 06:18:54,387] {logging_mixin.py:109} WARNING -   File "/home/***/.local/lib/python3.7/site-packages/sqlalchemy/engine/base.py", line 2340, in _wrap_pool_connect
    e, dialect, self
[2022-09-16 06:18:54,387] {logging_mixin.py:109} WARNING -   File "/home/***/.local/lib/python3.7/site-packages/sqlalchemy/engine/base.py", line 1584, in _handle_dbapi_exception_noconnection
    sqlalchemy_exception, with_traceback=exc_info[2], from_=e
[2022-09-16 06:18:54,388] {logging_mixin.py:109} WARNING -   File "/home/***/.local/lib/python3.7/site-packages/sqlalchemy/util/compat.py", line 182, in raise_
    raise exception
[2022-09-16 06:18:54,389] {logging_mixin.py:109} WARNING -   File "/home/***/.local/lib/python3.7/site-packages/sqlalchemy/engine/base.py", line 2336, in _wrap_pool_connect
    return fn()
[2022-09-16 06:18:54,390] {logging_mixin.py:109} WARNING -   File "/home/***/.local/lib/python3.7/site-packages/sqlalchemy/pool/base.py", line 364, in connect
    return _ConnectionFairy._checkout(self)
[2022-09-16 06:18:54,390] {logging_mixin.py:109} WARNING -   File "/home/***/.local/lib/python3.7/site-packages/sqlalchemy/pool/base.py", line 778, in _checkout
    fairy = _ConnectionRecord.checkout(pool)
[2022-09-16 06:18:54,391] {logging_mixin.py:109} WARNING -   File "/home/***/.local/lib/python3.7/site-packages/sqlalchemy/pool/base.py", line 495, in checkout
    rec = pool._do_get()
[2022-09-16 06:18:54,391] {logging_mixin.py:109} WARNING -   File "/home/***/.local/lib/python3.7/site-packages/sqlalchemy/pool/impl.py", line 140, in _do_get
    self._dec_overflow()
[2022-09-16 06:18:54,392] {logging_mixin.py:109} WARNING -   File "/home/***/.local/lib/python3.7/site-packages/sqlalchemy/util/langhelpers.py", line 70, in __exit__
    with_traceback=exc_tb,
[2022-09-16 06:18:54,393] {logging_mixin.py:109} WARNING -   File "/home/***/.local/lib/python3.7/site-packages/sqlalchemy/util/compat.py", line 182, in raise_
    raise exception
[2022-09-16 06:18:54,393] {logging_mixin.py:109} WARNING -   File "/home/***/.local/lib/python3.7/site-packages/sqlalchemy/pool/impl.py", line 137, in _do_get
    return self._create_connection()
[2022-09-16 06:18:54,394] {logging_mixin.py:109} WARNING -   File "/home/***/.local/lib/python3.7/site-packages/sqlalchemy/pool/base.py", line 309, in _create_connection
    return _ConnectionRecord(self)
[2022-09-16 06:18:54,395] {logging_mixin.py:109} WARNING -   File "/home/***/.local/lib/python3.7/site-packages/sqlalchemy/pool/base.py", line 440, in __init__
    self.__connect(first_connect_check=True)
[2022-09-16 06:18:54,395] {logging_mixin.py:109} WARNING -   File "/home/***/.local/lib/python3.7/site-packages/sqlalchemy/pool/base.py", line 661, in __connect
    pool.logger.debug("Error on connect(): %s", e)
[2022-09-16 06:18:54,396] {logging_mixin.py:109} WARNING -   File "/home/***/.local/lib/python3.7/site-packages/sqlalchemy/util/langhelpers.py", line 70, in __exit__
    with_traceback=exc_tb,
[2022-09-16 06:18:54,396] {logging_mixin.py:109} WARNING -   File "/home/***/.local/lib/python3.7/site-packages/sqlalchemy/util/compat.py", line 182, in raise_
    raise exception
[2022-09-16 06:18:54,397] {logging_mixin.py:109} WARNING -   File "/home/***/.local/lib/python3.7/site-packages/sqlalchemy/pool/base.py", line 656, in __connect
    connection = pool._invoke_creator(self)
[2022-09-16 06:18:54,397] {logging_mixin.py:109} WARNING -   File "/home/***/.local/lib/python3.7/site-packages/sqlalchemy/engine/strategies.py", line 114, in connect
    return dialect.connect(*cargs, **cparams)
[2022-09-16 06:18:54,398] {logging_mixin.py:109} WARNING -   File "/home/***/.local/lib/python3.7/site-packages/sqlalchemy/engine/default.py", line 508, in connect
    return self.dbapi.connect(*cargs, **cparams)
[2022-09-16 06:18:54,398] {logging_mixin.py:109} WARNING -   File "/home/***/.local/lib/python3.7/site-packages/psycopg2/__init__.py", line 122, in connect
    conn = _connect(dsn, connection_factory=connection_factory, **kwasync)
[2022-09-16 06:18:54,399] {logging_mixin.py:109} WARNING - sqlalchemy.exc.OperationalError: (psycopg2.OperationalError) could not translate host name "pgdatabase" to address: Temporary failure in name resolution

(Background on this error at: http://sqlalche.me/e/13/e3q8)
[2022-09-16 06:18:54,399] {logging_mixin.py:109} WARNING - 
During handling of the above exception, another exception occurred:
[2022-09-16 06:18:54,400] {logging_mixin.py:109} WARNING - Traceback (most recent call last):
[2022-09-16 06:18:54,400] {logging_mixin.py:109} WARNING -   File "/usr/local/lib/python3.7/logging/__init__.py", line 1025, in emit
    msg = self.format(record)
[2022-09-16 06:18:54,401] {logging_mixin.py:109} WARNING -   File "/usr/local/lib/python3.7/logging/__init__.py", line 869, in format
    return fmt.format(record)
[2022-09-16 06:18:54,401] {logging_mixin.py:109} WARNING -   File "/usr/local/lib/python3.7/logging/__init__.py", line 616, in format
    record.exc_text = self.formatException(record.exc_info)
[2022-09-16 06:18:54,401] {logging_mixin.py:109} WARNING -   File "/usr/local/lib/python3.7/logging/__init__.py", line 566, in formatException
    traceback.print_exception(ei[0], ei[1], tb, None, sio)
[2022-09-16 06:18:54,402] {logging_mixin.py:109} WARNING -   File "/usr/local/lib/python3.7/traceback.py", line 104, in print_exception
    type(value), value, tb, limit=limit).format(chain=chain):
[2022-09-16 06:18:54,402] {logging_mixin.py:109} WARNING -   File "/usr/local/lib/python3.7/traceback.py", line 508, in __init__
    capture_locals=capture_locals)
[2022-09-16 06:18:54,403] {logging_mixin.py:109} WARNING -   File "/usr/local/lib/python3.7/traceback.py", line 363, in extract
    f.line
[2022-09-16 06:18:54,403] {logging_mixin.py:109} WARNING -   File "/usr/local/lib/python3.7/traceback.py", line 285, in line
    self._line = linecache.getline(self.filename, self.lineno).strip()
[2022-09-16 06:18:54,404] {logging_mixin.py:109} WARNING -   File "/usr/local/lib/python3.7/linecache.py", line 16, in getline
    lines = getlines(filename, module_globals)
[2022-09-16 06:18:54,404] {logging_mixin.py:109} WARNING -   File "/usr/local/lib/python3.7/linecache.py", line 47, in getlines
    return updatecache(filename, module_globals)
[2022-09-16 06:18:54,405] {logging_mixin.py:109} WARNING -   File "/usr/local/lib/python3.7/linecache.py", line 136, in updatecache
    with tokenize.open(fullname) as fp:
[2022-09-16 06:18:54,405] {logging_mixin.py:109} WARNING -   File "/usr/local/lib/python3.7/tokenize.py", line 449, in open
    encoding, lines = detect_encoding(buffer.readline)
[2022-09-16 06:18:54,405] {logging_mixin.py:109} WARNING -   File "/usr/local/lib/python3.7/tokenize.py", line 418, in detect_encoding
    first = read_or_stop()
[2022-09-16 06:18:54,406] {logging_mixin.py:109} WARNING -   File "/usr/local/lib/python3.7/tokenize.py", line 376, in read_or_stop
    return readline()
[2022-09-16 06:18:54,406] {logging_mixin.py:109} WARNING -   File "/home/***/.local/lib/python3.7/site-packages/***/models/taskinstance.py", line 1410, in signal_handler
    raise AirflowException("Task received SIGTERM signal")
[2022-09-16 06:18:54,406] {logging_mixin.py:109} WARNING - ***.exceptions.AirflowException: Task received SIGTERM signal
[2022-09-16 06:18:54,407] {logging_mixin.py:109} WARNING - Call stack:
[2022-09-16 06:18:55,522] {logging_mixin.py:109} WARNING -   File "/home/***/.local/bin/***", line 8, in <module>
    sys.exit(main())
[2022-09-16 06:18:55,524] {logging_mixin.py:109} WARNING -   File "/home/***/.local/lib/python3.7/site-packages/***/__main__.py", line 48, in main
    args.func(args)
[2022-09-16 06:18:55,526] {logging_mixin.py:109} WARNING -   File "/home/***/.local/lib/python3.7/site-packages/***/cli/cli_parser.py", line 48, in command
    return func(*args, **kwargs)
[2022-09-16 06:18:55,527] {logging_mixin.py:109} WARNING -   File "/home/***/.local/lib/python3.7/site-packages/***/utils/cli.py", line 92, in wrapper
    return f(*args, **kwargs)
[2022-09-16 06:18:55,529] {logging_mixin.py:109} WARNING -   File "/home/***/.local/lib/python3.7/site-packages/***/cli/commands/scheduler_command.py", line 75, in scheduler
    _run_scheduler_job(args=args)
[2022-09-16 06:18:55,531] {logging_mixin.py:109} WARNING -   File "/home/***/.local/lib/python3.7/site-packages/***/cli/commands/scheduler_command.py", line 46, in _run_scheduler_job
    job.run()
[2022-09-16 06:18:55,532] {logging_mixin.py:109} WARNING -   File "/home/***/.local/lib/python3.7/site-packages/***/jobs/base_job.py", line 245, in run
    self._execute()
[2022-09-16 06:18:55,534] {logging_mixin.py:109} WARNING -   File "/home/***/.local/lib/python3.7/site-packages/***/jobs/scheduler_job.py", line 620, in _execute
    self.executor.start()
[2022-09-16 06:18:55,535] {logging_mixin.py:109} WARNING -   File "/home/***/.local/lib/python3.7/site-packages/***/executors/local_executor.py", line 356, in start
    self.impl.start()
[2022-09-16 06:18:55,537] {logging_mixin.py:109} WARNING -   File "/home/***/.local/lib/python3.7/site-packages/***/executors/local_executor.py", line 298, in start
    worker.start()
[2022-09-16 06:18:55,539] {logging_mixin.py:109} WARNING -   File "/usr/local/lib/python3.7/multiprocessing/process.py", line 112, in start
    self._popen = self._Popen(self)
[2022-09-16 06:18:55,540] {logging_mixin.py:109} WARNING -   File "/usr/local/lib/python3.7/multiprocessing/context.py", line 223, in _Popen
    return _default_context.get_context().Process._Popen(process_obj)
[2022-09-16 06:18:55,542] {logging_mixin.py:109} WARNING -   File "/usr/local/lib/python3.7/multiprocessing/context.py", line 277, in _Popen
    return Popen(process_obj)
[2022-09-16 06:18:55,544] {logging_mixin.py:109} WARNING -   File "/usr/local/lib/python3.7/multiprocessing/popen_fork.py", line 20, in __init__
    self._launch(process_obj)
[2022-09-16 06:18:55,545] {logging_mixin.py:109} WARNING -   File "/usr/local/lib/python3.7/multiprocessing/popen_fork.py", line 74, in _launch
    code = process_obj._bootstrap()
[2022-09-16 06:18:55,547] {logging_mixin.py:109} WARNING -   File "/usr/local/lib/python3.7/multiprocessing/process.py", line 297, in _bootstrap
    self.run()
[2022-09-16 06:18:55,548] {logging_mixin.py:109} WARNING -   File "/home/***/.local/lib/python3.7/site-packages/***/executors/local_executor.py", line 67, in run
    return super().run()
[2022-09-16 06:18:55,550] {logging_mixin.py:109} WARNING -   File "/usr/local/lib/python3.7/multiprocessing/process.py", line 99, in run
    self._target(*self._args, **self._kwargs)
[2022-09-16 06:18:55,551] {logging_mixin.py:109} WARNING -   File "/home/***/.local/lib/python3.7/site-packages/***/executors/local_executor.py", line 190, in do_work
    self.execute_work(key=key, command=command)
[2022-09-16 06:18:55,553] {logging_mixin.py:109} WARNING -   File "/home/***/.local/lib/python3.7/site-packages/***/executors/local_executor.py", line 84, in execute_work
    state = self._execute_work_in_fork(command)
[2022-09-16 06:18:55,555] {logging_mixin.py:109} WARNING -   File "/home/***/.local/lib/python3.7/site-packages/***/executors/local_executor.py", line 124, in _execute_work_in_fork
    args.func(args)
[2022-09-16 06:18:55,556] {logging_mixin.py:109} WARNING -   File "/home/***/.local/lib/python3.7/site-packages/***/cli/cli_parser.py", line 48, in command
    return func(*args, **kwargs)
[2022-09-16 06:18:55,558] {logging_mixin.py:109} WARNING -   File "/home/***/.local/lib/python3.7/site-packages/***/utils/cli.py", line 92, in wrapper
    return f(*args, **kwargs)
[2022-09-16 06:18:55,559] {logging_mixin.py:109} WARNING -   File "/home/***/.local/lib/python3.7/site-packages/***/cli/commands/task_command.py", line 298, in task_run
    _run_task_by_selected_method(args, dag, ti)
[2022-09-16 06:18:55,560] {logging_mixin.py:109} WARNING -   File "/home/***/.local/lib/python3.7/site-packages/***/cli/commands/task_command.py", line 105, in _run_task_by_selected_method
    _run_task_by_local_task_job(args, ti)
[2022-09-16 06:18:55,560] {logging_mixin.py:109} WARNING -   File "/home/***/.local/lib/python3.7/site-packages/***/cli/commands/task_command.py", line 163, in _run_task_by_local_task_job
    run_job.run()
[2022-09-16 06:18:55,561] {logging_mixin.py:109} WARNING -   File "/home/***/.local/lib/python3.7/site-packages/***/jobs/base_job.py", line 245, in run
    self._execute()
[2022-09-16 06:18:55,562] {logging_mixin.py:109} WARNING -   File "/home/***/.local/lib/python3.7/site-packages/***/jobs/local_task_job.py", line 103, in _execute
    self.task_runner.start()
[2022-09-16 06:18:55,563] {logging_mixin.py:109} WARNING -   File "/home/***/.local/lib/python3.7/site-packages/***/task/task_runner/standard_task_runner.py", line 41, in start
    self.process = self._start_by_fork()
[2022-09-16 06:18:55,564] {logging_mixin.py:109} WARNING -   File "/home/***/.local/lib/python3.7/site-packages/***/task/task_runner/standard_task_runner.py", line 92, in _start_by_fork
    self._task_instance.task_id,
[2022-09-16 06:18:55,564] {logging_mixin.py:109} WARNING -   File "/usr/local/lib/python3.7/logging/__init__.py", line 1413, in exception
    self.error(msg, *args, exc_info=exc_info, **kwargs)
[2022-09-16 06:18:55,565] {logging_mixin.py:109} WARNING -   File "/usr/local/lib/python3.7/logging/__init__.py", line 1407, in error
    self._log(ERROR, msg, args, **kwargs)
[2022-09-16 06:18:55,566] {logging_mixin.py:109} WARNING -   File "/usr/local/lib/python3.7/logging/__init__.py", line 1514, in _log
    self.handle(record)
[2022-09-16 06:18:55,567] {logging_mixin.py:109} WARNING -   File "/usr/local/lib/python3.7/logging/__init__.py", line 1524, in handle
    self.callHandlers(record)
[2022-09-16 06:18:55,568] {logging_mixin.py:109} WARNING -   File "/usr/local/lib/python3.7/logging/__init__.py", line 1586, in callHandlers
    hdlr.handle(record)
[2022-09-16 06:18:55,569] {logging_mixin.py:109} WARNING -   File "/usr/local/lib/python3.7/logging/__init__.py", line 894, in handle
    self.emit(record)
[2022-09-16 06:18:55,570] {logging_mixin.py:109} WARNING -   File "/home/***/.local/lib/python3.7/site-packages/***/utils/log/file_task_handler.py", line 67, in emit
    self.handler.emit(record)
[2022-09-16 06:18:55,621] {logging_mixin.py:109} WARNING - Message: 'Failed to execute job %s for task %s'
Arguments: (194, 'ingest')
[2022-09-16 06:18:55,707] {process_utils.py:70} INFO - Process psutil.Process(pid=795, status='terminated', exitcode=1, started='06:17:06') (795) terminated with exit code 1
