[2022-09-11 11:08:55,171] {taskinstance.py:1032} INFO - Dependencies all met for <TaskInstance: ZonesIngestionDag.ingest manual__2022-09-11T10:52:30.468879+00:00 [queued]>
[2022-09-11 11:08:55,356] {taskinstance.py:1032} INFO - Dependencies all met for <TaskInstance: ZonesIngestionDag.ingest manual__2022-09-11T10:52:30.468879+00:00 [queued]>
[2022-09-11 11:08:55,356] {taskinstance.py:1238} INFO - 
--------------------------------------------------------------------------------
[2022-09-11 11:08:55,356] {taskinstance.py:1239} INFO - Starting attempt 2 of 2
[2022-09-11 11:08:55,357] {taskinstance.py:1240} INFO - 
--------------------------------------------------------------------------------
[2022-09-11 11:08:55,542] {taskinstance.py:1259} INFO - Executing <Task(PythonOperator): ingest> on 2022-09-11 10:52:30.468879+00:00
[2022-09-11 11:08:55,546] {standard_task_runner.py:52} INFO - Started process 14447 to run task
[2022-09-11 11:08:55,554] {standard_task_runner.py:76} INFO - Running: ['***', 'tasks', 'run', 'ZonesIngestionDag', 'ingest', 'manual__2022-09-11T10:52:30.468879+00:00', '--job-id', '35', '--raw', '--subdir', 'DAGS_FOLDER/Zones_ingest.py', '--cfg-path', '/tmp/tmp7icge22o', '--error-file', '/tmp/tmp9nau3u_q']
[2022-09-11 11:08:55,555] {standard_task_runner.py:77} INFO - Job 35: Subtask ingest
[2022-09-11 11:08:55,641] {logging_mixin.py:109} INFO - Running <TaskInstance: ZonesIngestionDag.ingest manual__2022-09-11T10:52:30.468879+00:00 [running]> on host 6ae512137983
[2022-09-11 11:08:55,802] {taskinstance.py:1426} INFO - Exporting the following env vars:
AIRFLOW_CTX_DAG_OWNER=***
AIRFLOW_CTX_DAG_ID=ZonesIngestionDag
AIRFLOW_CTX_TASK_ID=ingest
AIRFLOW_CTX_EXECUTION_DATE=2022-09-11T10:52:30.468879+00:00
AIRFLOW_CTX_DAG_RUN_ID=manual__2022-09-11T10:52:30.468879+00:00
[2022-09-11 11:09:13,671] {taskinstance.py:1700} ERROR - Task failed with exception
Traceback (most recent call last):
  File "/home/airflow/.local/lib/python3.7/site-packages/airflow/models/taskinstance.py", line 1329, in _run_raw_task
    self._execute_task_with_callbacks(context)
  File "/home/airflow/.local/lib/python3.7/site-packages/airflow/models/taskinstance.py", line 1455, in _execute_task_with_callbacks
    result = self._execute_task(context, self.task)
  File "/home/airflow/.local/lib/python3.7/site-packages/airflow/models/taskinstance.py", line 1511, in _execute_task
    result = execute_callable(context=context)
  File "/home/airflow/.local/lib/python3.7/site-packages/airflow/operators/python.py", line 174, in execute
    return_value = self.execute_callable()
  File "/home/airflow/.local/lib/python3.7/site-packages/airflow/operators/python.py", line 185, in execute_callable
    return self.python_callable(*self.op_args, **self.op_kwargs)
  File "/opt/airflow/dags/Zones_ingest.py", line 28, in ingest_call
    logging.print("Finished ingesting data into the postgres database by PANDAS PARQUET")
AttributeError: module 'logging' has no attribute 'print'
[2022-09-11 11:09:13,733] {taskinstance.py:1277} INFO - Marking task as FAILED. dag_id=ZonesIngestionDag, task_id=ingest, execution_date=20220911T105230, start_date=20220911T110855, end_date=20220911T110913
[2022-09-11 11:09:13,846] {standard_task_runner.py:92} ERROR - Failed to execute job 35 for task ingest
Traceback (most recent call last):
  File "/home/airflow/.local/lib/python3.7/site-packages/airflow/task/task_runner/standard_task_runner.py", line 85, in _start_by_fork
    args.func(args, dag=self.dag)
  File "/home/airflow/.local/lib/python3.7/site-packages/airflow/cli/cli_parser.py", line 48, in command
    return func(*args, **kwargs)
  File "/home/airflow/.local/lib/python3.7/site-packages/airflow/utils/cli.py", line 92, in wrapper
    return f(*args, **kwargs)
  File "/home/airflow/.local/lib/python3.7/site-packages/airflow/cli/commands/task_command.py", line 298, in task_run
    _run_task_by_selected_method(args, dag, ti)
  File "/home/airflow/.local/lib/python3.7/site-packages/airflow/cli/commands/task_command.py", line 107, in _run_task_by_selected_method
    _run_raw_task(args, ti)
  File "/home/airflow/.local/lib/python3.7/site-packages/airflow/cli/commands/task_command.py", line 184, in _run_raw_task
    error_file=args.error_file,
  File "/home/airflow/.local/lib/python3.7/site-packages/airflow/utils/session.py", line 70, in wrapper
    return func(*args, session=session, **kwargs)
  File "/home/airflow/.local/lib/python3.7/site-packages/airflow/models/taskinstance.py", line 1329, in _run_raw_task
    self._execute_task_with_callbacks(context)
  File "/home/airflow/.local/lib/python3.7/site-packages/airflow/models/taskinstance.py", line 1455, in _execute_task_with_callbacks
    result = self._execute_task(context, self.task)
  File "/home/airflow/.local/lib/python3.7/site-packages/airflow/models/taskinstance.py", line 1511, in _execute_task
    result = execute_callable(context=context)
  File "/home/airflow/.local/lib/python3.7/site-packages/airflow/operators/python.py", line 174, in execute
    return_value = self.execute_callable()
  File "/home/airflow/.local/lib/python3.7/site-packages/airflow/operators/python.py", line 185, in execute_callable
    return self.python_callable(*self.op_args, **self.op_kwargs)
  File "/opt/airflow/dags/Zones_ingest.py", line 28, in ingest_call
    logging.print("Finished ingesting data into the postgres database by PANDAS PARQUET")
AttributeError: module 'logging' has no attribute 'print'
[2022-09-11 11:09:13,875] {local_task_job.py:154} INFO - Task exited with return code 1
[2022-09-11 11:09:14,025] {local_task_job.py:264} INFO - 0 downstream tasks scheduled from follow-on schedule check
