[2022-09-11 16:24:11,113] {taskinstance.py:1032} INFO - Dependencies all met for <TaskInstance: FHVIngestionDag.ingest scheduled__2019-02-01T06:00:00+00:00 [queued]>
[2022-09-11 16:24:11,133] {taskinstance.py:1032} INFO - Dependencies all met for <TaskInstance: FHVIngestionDag.ingest scheduled__2019-02-01T06:00:00+00:00 [queued]>
[2022-09-11 16:24:11,133] {taskinstance.py:1238} INFO - 
--------------------------------------------------------------------------------
[2022-09-11 16:24:11,134] {taskinstance.py:1239} INFO - Starting attempt 1 of 1
[2022-09-11 16:24:11,134] {taskinstance.py:1240} INFO - 
--------------------------------------------------------------------------------
[2022-09-11 16:24:11,216] {taskinstance.py:1259} INFO - Executing <Task(PythonOperator): ingest> on 2019-02-01 06:00:00+00:00
[2022-09-11 16:24:11,221] {standard_task_runner.py:52} INFO - Started process 6833 to run task
[2022-09-11 16:24:11,225] {standard_task_runner.py:76} INFO - Running: ['***', 'tasks', 'run', 'FHVIngestionDag', 'ingest', 'scheduled__2019-02-01T06:00:00+00:00', '--job-id', '77', '--raw', '--subdir', 'DAGS_FOLDER/FHV_ingest_19.py', '--cfg-path', '/tmp/tmpg1gtauxo', '--error-file', '/tmp/tmpmp4m2_dt']
[2022-09-11 16:24:11,226] {standard_task_runner.py:77} INFO - Job 77: Subtask ingest
[2022-09-11 16:24:11,328] {logging_mixin.py:109} INFO - Running <TaskInstance: FHVIngestionDag.ingest scheduled__2019-02-01T06:00:00+00:00 [running]> on host 6ae512137983
[2022-09-11 16:24:11,424] {logging_mixin.py:109} WARNING - /home/***/.local/lib/python3.7/site-packages/***/utils/context.py:152 AirflowContextDeprecationWarning: Accessing 'execution_date' from the template is deprecated and will be removed in a future version. Please use 'data_interval_start' or 'logical_date' instead.
[2022-09-11 16:24:11,585] {taskinstance.py:1426} INFO - Exporting the following env vars:
AIRFLOW_CTX_DAG_OWNER=***
AIRFLOW_CTX_DAG_ID=FHVIngestionDag
AIRFLOW_CTX_TASK_ID=ingest
AIRFLOW_CTX_EXECUTION_DATE=2019-02-01T06:00:00+00:00
AIRFLOW_CTX_DAG_RUN_ID=scheduled__2019-02-01T06:00:00+00:00
[2022-09-11 16:24:13,047] {taskinstance.py:1700} ERROR - Task failed with exception
Traceback (most recent call last):
  File "/home/airflow/.local/lib/python3.7/site-packages/airflow/models/taskinstance.py", line 1329, in _run_raw_task
    self._execute_task_with_callbacks(context)
  File "/home/airflow/.local/lib/python3.7/site-packages/airflow/models/taskinstance.py", line 1455, in _execute_task_with_callbacks
    result = self._execute_task(context, self.task)
  File "/home/airflow/.local/lib/python3.7/site-packages/airflow/models/taskinstance.py", line 1511, in _execute_task
    result = execute_callable(context=context)
  File "/home/airflow/.local/lib/python3.7/site-packages/airflow/operators/python.py", line 174, in execute
    return_value = self.execute_callable()
  File "/home/airflow/.local/lib/python3.7/site-packages/airflow/operators/python.py", line 185, in execute_callable
    return self.python_callable(*self.op_args, **self.op_kwargs)
  File "/opt/airflow/dags/FHV_ingest_19.py", line 22, in ingest_call
    outparq = pd.read_parquet(filePath)
  File "/home/airflow/.local/lib/python3.7/site-packages/pandas/io/parquet.py", line 500, in read_parquet
    **kwargs,
  File "/home/airflow/.local/lib/python3.7/site-packages/pandas/io/parquet.py", line 241, in read
    ).to_pandas(**to_pandas_kwargs)
  File "pyarrow/array.pxi", line 757, in pyarrow.lib._PandasConvertible.to_pandas
  File "pyarrow/table.pxi", line 1748, in pyarrow.lib.Table._to_pandas
  File "/home/airflow/.local/lib/python3.7/site-packages/pyarrow/pandas_compat.py", line 789, in table_to_blockmanager
    blocks = _table_to_blocks(options, table, categories, ext_columns_dtypes)
  File "/home/airflow/.local/lib/python3.7/site-packages/pyarrow/pandas_compat.py", line 1129, in _table_to_blocks
    list(extension_columns.keys()))
  File "pyarrow/table.pxi", line 1156, in pyarrow.lib.table_to_blocks
  File "pyarrow/error.pxi", line 99, in pyarrow.lib.check_status
pyarrow.lib.ArrowInvalid: Casting from timestamp[us] to timestamp[ns] would result in out of bounds timestamp: 33106123800000000
[2022-09-11 16:24:13,170] {taskinstance.py:1277} INFO - Marking task as FAILED. dag_id=FHVIngestionDag, task_id=ingest, execution_date=20190201T060000, start_date=20220911T162411, end_date=20220911T162413
[2022-09-11 16:24:13,371] {standard_task_runner.py:92} ERROR - Failed to execute job 77 for task ingest
Traceback (most recent call last):
  File "/home/airflow/.local/lib/python3.7/site-packages/airflow/task/task_runner/standard_task_runner.py", line 85, in _start_by_fork
    args.func(args, dag=self.dag)
  File "/home/airflow/.local/lib/python3.7/site-packages/airflow/cli/cli_parser.py", line 48, in command
    return func(*args, **kwargs)
  File "/home/airflow/.local/lib/python3.7/site-packages/airflow/utils/cli.py", line 92, in wrapper
    return f(*args, **kwargs)
  File "/home/airflow/.local/lib/python3.7/site-packages/airflow/cli/commands/task_command.py", line 298, in task_run
    _run_task_by_selected_method(args, dag, ti)
  File "/home/airflow/.local/lib/python3.7/site-packages/airflow/cli/commands/task_command.py", line 107, in _run_task_by_selected_method
    _run_raw_task(args, ti)
  File "/home/airflow/.local/lib/python3.7/site-packages/airflow/cli/commands/task_command.py", line 184, in _run_raw_task
    error_file=args.error_file,
  File "/home/airflow/.local/lib/python3.7/site-packages/airflow/utils/session.py", line 70, in wrapper
    return func(*args, session=session, **kwargs)
  File "/home/airflow/.local/lib/python3.7/site-packages/airflow/models/taskinstance.py", line 1329, in _run_raw_task
    self._execute_task_with_callbacks(context)
  File "/home/airflow/.local/lib/python3.7/site-packages/airflow/models/taskinstance.py", line 1455, in _execute_task_with_callbacks
    result = self._execute_task(context, self.task)
  File "/home/airflow/.local/lib/python3.7/site-packages/airflow/models/taskinstance.py", line 1511, in _execute_task
    result = execute_callable(context=context)
  File "/home/airflow/.local/lib/python3.7/site-packages/airflow/operators/python.py", line 174, in execute
    return_value = self.execute_callable()
  File "/home/airflow/.local/lib/python3.7/site-packages/airflow/operators/python.py", line 185, in execute_callable
    return self.python_callable(*self.op_args, **self.op_kwargs)
  File "/opt/airflow/dags/FHV_ingest_19.py", line 22, in ingest_call
    outparq = pd.read_parquet(filePath)
  File "/home/airflow/.local/lib/python3.7/site-packages/pandas/io/parquet.py", line 500, in read_parquet
    **kwargs,
  File "/home/airflow/.local/lib/python3.7/site-packages/pandas/io/parquet.py", line 241, in read
    ).to_pandas(**to_pandas_kwargs)
  File "pyarrow/array.pxi", line 757, in pyarrow.lib._PandasConvertible.to_pandas
  File "pyarrow/table.pxi", line 1748, in pyarrow.lib.Table._to_pandas
  File "/home/airflow/.local/lib/python3.7/site-packages/pyarrow/pandas_compat.py", line 789, in table_to_blockmanager
    blocks = _table_to_blocks(options, table, categories, ext_columns_dtypes)
  File "/home/airflow/.local/lib/python3.7/site-packages/pyarrow/pandas_compat.py", line 1129, in _table_to_blocks
    list(extension_columns.keys()))
  File "pyarrow/table.pxi", line 1156, in pyarrow.lib.table_to_blocks
  File "pyarrow/error.pxi", line 99, in pyarrow.lib.check_status
pyarrow.lib.ArrowInvalid: Casting from timestamp[us] to timestamp[ns] would result in out of bounds timestamp: 33106123800000000
[2022-09-11 16:24:13,492] {local_task_job.py:154} INFO - Task exited with return code 1
[2022-09-11 16:24:13,662] {local_task_job.py:264} INFO - 0 downstream tasks scheduled from follow-on schedule check
[2022-09-15 05:19:49,247] {taskinstance.py:1032} INFO - Dependencies all met for <TaskInstance: FHVIngestionDag.ingest scheduled__2019-02-01T06:00:00+00:00 [queued]>
[2022-09-15 05:19:49,292] {taskinstance.py:1032} INFO - Dependencies all met for <TaskInstance: FHVIngestionDag.ingest scheduled__2019-02-01T06:00:00+00:00 [queued]>
[2022-09-15 05:19:49,292] {taskinstance.py:1238} INFO - 
--------------------------------------------------------------------------------
[2022-09-15 05:19:49,292] {taskinstance.py:1239} INFO - Starting attempt 1 of 1
[2022-09-15 05:19:49,293] {taskinstance.py:1240} INFO - 
--------------------------------------------------------------------------------
[2022-09-15 05:19:49,379] {taskinstance.py:1259} INFO - Executing <Task(PythonOperator): ingest> on 2019-02-01 06:00:00+00:00
[2022-09-15 05:19:49,383] {standard_task_runner.py:52} INFO - Started process 361 to run task
[2022-09-15 05:19:49,386] {standard_task_runner.py:76} INFO - Running: ['***', 'tasks', 'run', 'FHVIngestionDag', 'ingest', 'scheduled__2019-02-01T06:00:00+00:00', '--job-id', '149', '--raw', '--subdir', 'DAGS_FOLDER/FHV_ingest_19.py', '--cfg-path', '/tmp/tmp12q076er', '--error-file', '/tmp/tmporuqvchq']
[2022-09-15 05:19:49,387] {standard_task_runner.py:77} INFO - Job 149: Subtask ingest
[2022-09-15 05:19:49,596] {logging_mixin.py:109} INFO - Running <TaskInstance: FHVIngestionDag.ingest scheduled__2019-02-01T06:00:00+00:00 [running]> on host c071d865a623
[2022-09-15 05:19:49,782] {logging_mixin.py:109} WARNING - /home/***/.local/lib/python3.7/site-packages/***/utils/context.py:152 AirflowContextDeprecationWarning: Accessing 'execution_date' from the template is deprecated and will be removed in a future version. Please use 'data_interval_start' or 'logical_date' instead.
[2022-09-15 05:19:50,033] {taskinstance.py:1426} INFO - Exporting the following env vars:
AIRFLOW_CTX_DAG_OWNER=***
AIRFLOW_CTX_DAG_ID=FHVIngestionDag
AIRFLOW_CTX_TASK_ID=ingest
AIRFLOW_CTX_EXECUTION_DATE=2019-02-01T06:00:00+00:00
AIRFLOW_CTX_DAG_RUN_ID=scheduled__2019-02-01T06:00:00+00:00
[2022-09-15 05:19:50,034] {logging_mixin.py:109} INFO - 3
[2022-09-15 05:19:51,772] {taskinstance.py:1700} ERROR - Task failed with exception
Traceback (most recent call last):
  File "/home/airflow/.local/lib/python3.7/site-packages/airflow/models/taskinstance.py", line 1329, in _run_raw_task
    self._execute_task_with_callbacks(context)
  File "/home/airflow/.local/lib/python3.7/site-packages/airflow/models/taskinstance.py", line 1455, in _execute_task_with_callbacks
    result = self._execute_task(context, self.task)
  File "/home/airflow/.local/lib/python3.7/site-packages/airflow/models/taskinstance.py", line 1511, in _execute_task
    result = execute_callable(context=context)
  File "/home/airflow/.local/lib/python3.7/site-packages/airflow/operators/python.py", line 174, in execute
    return_value = self.execute_callable()
  File "/home/airflow/.local/lib/python3.7/site-packages/airflow/operators/python.py", line 185, in execute_callable
    return self.python_callable(*self.op_args, **self.op_kwargs)
  File "/opt/airflow/dags/FHV_ingest_19.py", line 25, in ingest_call
    outparq = pd.read_parquet(filePath)
  File "/home/airflow/.local/lib/python3.7/site-packages/pandas/io/parquet.py", line 500, in read_parquet
    **kwargs,
  File "/home/airflow/.local/lib/python3.7/site-packages/pandas/io/parquet.py", line 241, in read
    ).to_pandas(**to_pandas_kwargs)
  File "pyarrow/array.pxi", line 757, in pyarrow.lib._PandasConvertible.to_pandas
  File "pyarrow/table.pxi", line 1748, in pyarrow.lib.Table._to_pandas
  File "/home/airflow/.local/lib/python3.7/site-packages/pyarrow/pandas_compat.py", line 789, in table_to_blockmanager
    blocks = _table_to_blocks(options, table, categories, ext_columns_dtypes)
  File "/home/airflow/.local/lib/python3.7/site-packages/pyarrow/pandas_compat.py", line 1129, in _table_to_blocks
    list(extension_columns.keys()))
  File "pyarrow/table.pxi", line 1156, in pyarrow.lib.table_to_blocks
  File "pyarrow/error.pxi", line 99, in pyarrow.lib.check_status
pyarrow.lib.ArrowInvalid: Casting from timestamp[us] to timestamp[ns] would result in out of bounds timestamp: 33106123800000000
[2022-09-15 05:19:51,898] {taskinstance.py:1277} INFO - Marking task as FAILED. dag_id=FHVIngestionDag, task_id=ingest, execution_date=20190201T060000, start_date=20220915T051949, end_date=20220915T051951
[2022-09-15 05:19:52,138] {standard_task_runner.py:92} ERROR - Failed to execute job 149 for task ingest
Traceback (most recent call last):
  File "/home/airflow/.local/lib/python3.7/site-packages/airflow/task/task_runner/standard_task_runner.py", line 85, in _start_by_fork
    args.func(args, dag=self.dag)
  File "/home/airflow/.local/lib/python3.7/site-packages/airflow/cli/cli_parser.py", line 48, in command
    return func(*args, **kwargs)
  File "/home/airflow/.local/lib/python3.7/site-packages/airflow/utils/cli.py", line 92, in wrapper
    return f(*args, **kwargs)
  File "/home/airflow/.local/lib/python3.7/site-packages/airflow/cli/commands/task_command.py", line 298, in task_run
    _run_task_by_selected_method(args, dag, ti)
  File "/home/airflow/.local/lib/python3.7/site-packages/airflow/cli/commands/task_command.py", line 107, in _run_task_by_selected_method
    _run_raw_task(args, ti)
  File "/home/airflow/.local/lib/python3.7/site-packages/airflow/cli/commands/task_command.py", line 184, in _run_raw_task
    error_file=args.error_file,
  File "/home/airflow/.local/lib/python3.7/site-packages/airflow/utils/session.py", line 70, in wrapper
    return func(*args, session=session, **kwargs)
  File "/home/airflow/.local/lib/python3.7/site-packages/airflow/models/taskinstance.py", line 1329, in _run_raw_task
    self._execute_task_with_callbacks(context)
  File "/home/airflow/.local/lib/python3.7/site-packages/airflow/models/taskinstance.py", line 1455, in _execute_task_with_callbacks
    result = self._execute_task(context, self.task)
  File "/home/airflow/.local/lib/python3.7/site-packages/airflow/models/taskinstance.py", line 1511, in _execute_task
    result = execute_callable(context=context)
  File "/home/airflow/.local/lib/python3.7/site-packages/airflow/operators/python.py", line 174, in execute
    return_value = self.execute_callable()
  File "/home/airflow/.local/lib/python3.7/site-packages/airflow/operators/python.py", line 185, in execute_callable
    return self.python_callable(*self.op_args, **self.op_kwargs)
  File "/opt/airflow/dags/FHV_ingest_19.py", line 25, in ingest_call
    outparq = pd.read_parquet(filePath)
  File "/home/airflow/.local/lib/python3.7/site-packages/pandas/io/parquet.py", line 500, in read_parquet
    **kwargs,
  File "/home/airflow/.local/lib/python3.7/site-packages/pandas/io/parquet.py", line 241, in read
    ).to_pandas(**to_pandas_kwargs)
  File "pyarrow/array.pxi", line 757, in pyarrow.lib._PandasConvertible.to_pandas
  File "pyarrow/table.pxi", line 1748, in pyarrow.lib.Table._to_pandas
  File "/home/airflow/.local/lib/python3.7/site-packages/pyarrow/pandas_compat.py", line 789, in table_to_blockmanager
    blocks = _table_to_blocks(options, table, categories, ext_columns_dtypes)
  File "/home/airflow/.local/lib/python3.7/site-packages/pyarrow/pandas_compat.py", line 1129, in _table_to_blocks
    list(extension_columns.keys()))
  File "pyarrow/table.pxi", line 1156, in pyarrow.lib.table_to_blocks
  File "pyarrow/error.pxi", line 99, in pyarrow.lib.check_status
pyarrow.lib.ArrowInvalid: Casting from timestamp[us] to timestamp[ns] would result in out of bounds timestamp: 33106123800000000
[2022-09-15 05:19:52,189] {local_task_job.py:154} INFO - Task exited with return code 1
[2022-09-15 05:19:52,345] {local_task_job.py:264} INFO - 0 downstream tasks scheduled from follow-on schedule check
