[2022-09-11 11:12:58,780] {taskinstance.py:1032} INFO - Dependencies all met for <TaskInstance: ZonesIngestionDag.ingest manual__2022-09-11T10:52:30.468879+00:00 [queued]>
[2022-09-11 11:12:58,794] {taskinstance.py:1032} INFO - Dependencies all met for <TaskInstance: ZonesIngestionDag.ingest manual__2022-09-11T10:52:30.468879+00:00 [queued]>
[2022-09-11 11:12:58,794] {taskinstance.py:1238} INFO - 
--------------------------------------------------------------------------------
[2022-09-11 11:12:58,795] {taskinstance.py:1239} INFO - Starting attempt 3 of 3
[2022-09-11 11:12:58,795] {taskinstance.py:1240} INFO - 
--------------------------------------------------------------------------------
[2022-09-11 11:12:58,878] {taskinstance.py:1259} INFO - Executing <Task(PythonOperator): ingest> on 2022-09-11 10:52:30.468879+00:00
[2022-09-11 11:12:58,882] {standard_task_runner.py:52} INFO - Started process 14788 to run task
[2022-09-11 11:12:58,885] {standard_task_runner.py:76} INFO - Running: ['***', 'tasks', 'run', 'ZonesIngestionDag', 'ingest', 'manual__2022-09-11T10:52:30.468879+00:00', '--job-id', '37', '--raw', '--subdir', 'DAGS_FOLDER/Zones_ingest.py', '--cfg-path', '/tmp/tmp8olbjpk9', '--error-file', '/tmp/tmp623de9yu']
[2022-09-11 11:12:58,886] {standard_task_runner.py:77} INFO - Job 37: Subtask ingest
[2022-09-11 11:12:59,140] {logging_mixin.py:109} INFO - Running <TaskInstance: ZonesIngestionDag.ingest manual__2022-09-11T10:52:30.468879+00:00 [running]> on host 6ae512137983
[2022-09-11 11:13:00,878] {taskinstance.py:1426} INFO - Exporting the following env vars:
AIRFLOW_CTX_DAG_OWNER=***
AIRFLOW_CTX_DAG_ID=ZonesIngestionDag
AIRFLOW_CTX_TASK_ID=ingest
AIRFLOW_CTX_EXECUTION_DATE=2022-09-11T10:52:30.468879+00:00
AIRFLOW_CTX_DAG_RUN_ID=manual__2022-09-11T10:52:30.468879+00:00
[2022-09-11 11:13:07,437] {taskinstance.py:1700} ERROR - Task failed with exception
Traceback (most recent call last):
  File "/home/airflow/.local/lib/python3.7/site-packages/airflow/models/taskinstance.py", line 1329, in _run_raw_task
    self._execute_task_with_callbacks(context)
  File "/home/airflow/.local/lib/python3.7/site-packages/airflow/models/taskinstance.py", line 1455, in _execute_task_with_callbacks
    result = self._execute_task(context, self.task)
  File "/home/airflow/.local/lib/python3.7/site-packages/airflow/models/taskinstance.py", line 1511, in _execute_task
    result = execute_callable(context=context)
  File "/home/airflow/.local/lib/python3.7/site-packages/airflow/operators/python.py", line 174, in execute
    return_value = self.execute_callable()
  File "/home/airflow/.local/lib/python3.7/site-packages/airflow/operators/python.py", line 185, in execute_callable
    return self.python_callable(*self.op_args, **self.op_kwargs)
  File "/opt/airflow/dags/Zones_ingest.py", line 28, in ingest_call
    logging.INFO("Finished ingesting data into the postgres database by PANDAS PARQUET")
TypeError: 'int' object is not callable
[2022-09-11 11:13:07,577] {taskinstance.py:1277} INFO - Marking task as FAILED. dag_id=ZonesIngestionDag, task_id=ingest, execution_date=20220911T105230, start_date=20220911T111258, end_date=20220911T111307
[2022-09-11 11:13:08,352] {standard_task_runner.py:92} ERROR - Failed to execute job 37 for task ingest
Traceback (most recent call last):
  File "/home/airflow/.local/lib/python3.7/site-packages/airflow/task/task_runner/standard_task_runner.py", line 85, in _start_by_fork
    args.func(args, dag=self.dag)
  File "/home/airflow/.local/lib/python3.7/site-packages/airflow/cli/cli_parser.py", line 48, in command
    return func(*args, **kwargs)
  File "/home/airflow/.local/lib/python3.7/site-packages/airflow/utils/cli.py", line 92, in wrapper
    return f(*args, **kwargs)
  File "/home/airflow/.local/lib/python3.7/site-packages/airflow/cli/commands/task_command.py", line 298, in task_run
    _run_task_by_selected_method(args, dag, ti)
  File "/home/airflow/.local/lib/python3.7/site-packages/airflow/cli/commands/task_command.py", line 107, in _run_task_by_selected_method
    _run_raw_task(args, ti)
  File "/home/airflow/.local/lib/python3.7/site-packages/airflow/cli/commands/task_command.py", line 184, in _run_raw_task
    error_file=args.error_file,
  File "/home/airflow/.local/lib/python3.7/site-packages/airflow/utils/session.py", line 70, in wrapper
    return func(*args, session=session, **kwargs)
  File "/home/airflow/.local/lib/python3.7/site-packages/airflow/models/taskinstance.py", line 1329, in _run_raw_task
    self._execute_task_with_callbacks(context)
  File "/home/airflow/.local/lib/python3.7/site-packages/airflow/models/taskinstance.py", line 1455, in _execute_task_with_callbacks
    result = self._execute_task(context, self.task)
  File "/home/airflow/.local/lib/python3.7/site-packages/airflow/models/taskinstance.py", line 1511, in _execute_task
    result = execute_callable(context=context)
  File "/home/airflow/.local/lib/python3.7/site-packages/airflow/operators/python.py", line 174, in execute
    return_value = self.execute_callable()
  File "/home/airflow/.local/lib/python3.7/site-packages/airflow/operators/python.py", line 185, in execute_callable
    return self.python_callable(*self.op_args, **self.op_kwargs)
  File "/opt/airflow/dags/Zones_ingest.py", line 28, in ingest_call
    logging.INFO("Finished ingesting data into the postgres database by PANDAS PARQUET")
TypeError: 'int' object is not callable
[2022-09-11 11:13:08,395] {local_task_job.py:154} INFO - Task exited with return code 1
[2022-09-11 11:13:08,924] {local_task_job.py:264} INFO - 0 downstream tasks scheduled from follow-on schedule check
