[2022-09-11 12:09:21,971] {taskinstance.py:1032} INFO - Dependencies all met for <TaskInstance: LocalIngestionDag.ingest scheduled__2022-08-01T06:00:00+00:00 [queued]>
[2022-09-11 12:09:22,011] {taskinstance.py:1032} INFO - Dependencies all met for <TaskInstance: LocalIngestionDag.ingest scheduled__2022-08-01T06:00:00+00:00 [queued]>
[2022-09-11 12:09:22,012] {taskinstance.py:1238} INFO - 
--------------------------------------------------------------------------------
[2022-09-11 12:09:22,013] {taskinstance.py:1239} INFO - Starting attempt 1 of 1
[2022-09-11 12:09:22,013] {taskinstance.py:1240} INFO - 
--------------------------------------------------------------------------------
[2022-09-11 12:09:23,471] {taskinstance.py:1259} INFO - Executing <Task(PythonOperator): ingest> on 2022-08-01 06:00:00+00:00
[2022-09-11 12:09:23,476] {standard_task_runner.py:52} INFO - Started process 19448 to run task
[2022-09-11 12:09:23,479] {standard_task_runner.py:76} INFO - Running: ['***', 'tasks', 'run', 'LocalIngestionDag', 'ingest', 'scheduled__2022-08-01T06:00:00+00:00', '--job-id', '54', '--raw', '--subdir', 'DAGS_FOLDER/ingest_data_dag.py', '--cfg-path', '/tmp/tmpl72qa3b1', '--error-file', '/tmp/tmp8gavl2o1']
[2022-09-11 12:09:23,481] {standard_task_runner.py:77} INFO - Job 54: Subtask ingest
[2022-09-11 12:09:24,957] {logging_mixin.py:109} INFO - Running <TaskInstance: LocalIngestionDag.ingest scheduled__2022-08-01T06:00:00+00:00 [running]> on host 6ae512137983
[2022-09-11 12:09:26,090] {logging_mixin.py:109} WARNING - /home/***/.local/lib/python3.7/site-packages/***/utils/context.py:152 AirflowContextDeprecationWarning: Accessing 'execution_date' from the template is deprecated and will be removed in a future version. Please use 'data_interval_start' or 'logical_date' instead.
[2022-09-11 12:09:26,906] {taskinstance.py:1426} INFO - Exporting the following env vars:
AIRFLOW_CTX_DAG_OWNER=***
AIRFLOW_CTX_DAG_ID=LocalIngestionDag
AIRFLOW_CTX_TASK_ID=ingest
AIRFLOW_CTX_EXECUTION_DATE=2022-08-01T06:00:00+00:00
AIRFLOW_CTX_DAG_RUN_ID=scheduled__2022-08-01T06:00:00+00:00
[2022-09-11 12:09:26,942] {taskinstance.py:1700} ERROR - Task failed with exception
Traceback (most recent call last):
  File "/home/airflow/.local/lib/python3.7/site-packages/airflow/models/taskinstance.py", line 1329, in _run_raw_task
    self._execute_task_with_callbacks(context)
  File "/home/airflow/.local/lib/python3.7/site-packages/airflow/models/taskinstance.py", line 1455, in _execute_task_with_callbacks
    result = self._execute_task(context, self.task)
  File "/home/airflow/.local/lib/python3.7/site-packages/airflow/models/taskinstance.py", line 1511, in _execute_task
    result = execute_callable(context=context)
  File "/home/airflow/.local/lib/python3.7/site-packages/airflow/operators/python.py", line 174, in execute
    return_value = self.execute_callable()
  File "/home/airflow/.local/lib/python3.7/site-packages/airflow/operators/python.py", line 185, in execute_callable
    return self.python_callable(*self.op_args, **self.op_kwargs)
  File "/opt/airflow/dags/ingest_data_dag.py", line 21, in ingest_call
    outparq = pd.read_parquet(filePath)
  File "/home/airflow/.local/lib/python3.7/site-packages/pandas/io/parquet.py", line 500, in read_parquet
    **kwargs,
  File "/home/airflow/.local/lib/python3.7/site-packages/pandas/io/parquet.py", line 240, in read
    path_or_handle, columns=columns, **kwargs
  File "/home/airflow/.local/lib/python3.7/site-packages/pyarrow/parquet.py", line 1869, in read_table
    coerce_int96_timestamp_unit=coerce_int96_timestamp_unit
  File "/home/airflow/.local/lib/python3.7/site-packages/pyarrow/parquet.py", line 1679, in __init__
    [fragment], schema=fragment.physical_schema,
  File "pyarrow/_dataset.pyx", line 952, in pyarrow._dataset.Fragment.physical_schema.__get__
  File "pyarrow/error.pxi", line 143, in pyarrow.lib.pyarrow_internal_check_status
  File "pyarrow/error.pxi", line 99, in pyarrow.lib.check_status
pyarrow.lib.ArrowInvalid: Could not open Parquet input source '<Buffer>': Parquet magic bytes not found in footer. Either the file is corrupted or this is not a parquet file.
[2022-09-11 12:09:26,958] {taskinstance.py:1277} INFO - Marking task as FAILED. dag_id=LocalIngestionDag, task_id=ingest, execution_date=20220801T060000, start_date=20220911T120921, end_date=20220911T120926
[2022-09-11 12:09:28,357] {standard_task_runner.py:92} ERROR - Failed to execute job 54 for task ingest
Traceback (most recent call last):
  File "/home/airflow/.local/lib/python3.7/site-packages/airflow/task/task_runner/standard_task_runner.py", line 85, in _start_by_fork
    args.func(args, dag=self.dag)
  File "/home/airflow/.local/lib/python3.7/site-packages/airflow/cli/cli_parser.py", line 48, in command
    return func(*args, **kwargs)
  File "/home/airflow/.local/lib/python3.7/site-packages/airflow/utils/cli.py", line 92, in wrapper
    return f(*args, **kwargs)
  File "/home/airflow/.local/lib/python3.7/site-packages/airflow/cli/commands/task_command.py", line 298, in task_run
    _run_task_by_selected_method(args, dag, ti)
  File "/home/airflow/.local/lib/python3.7/site-packages/airflow/cli/commands/task_command.py", line 107, in _run_task_by_selected_method
    _run_raw_task(args, ti)
  File "/home/airflow/.local/lib/python3.7/site-packages/airflow/cli/commands/task_command.py", line 184, in _run_raw_task
    error_file=args.error_file,
  File "/home/airflow/.local/lib/python3.7/site-packages/airflow/utils/session.py", line 70, in wrapper
    return func(*args, session=session, **kwargs)
  File "/home/airflow/.local/lib/python3.7/site-packages/airflow/models/taskinstance.py", line 1329, in _run_raw_task
    self._execute_task_with_callbacks(context)
  File "/home/airflow/.local/lib/python3.7/site-packages/airflow/models/taskinstance.py", line 1455, in _execute_task_with_callbacks
    result = self._execute_task(context, self.task)
  File "/home/airflow/.local/lib/python3.7/site-packages/airflow/models/taskinstance.py", line 1511, in _execute_task
    result = execute_callable(context=context)
  File "/home/airflow/.local/lib/python3.7/site-packages/airflow/operators/python.py", line 174, in execute
    return_value = self.execute_callable()
  File "/home/airflow/.local/lib/python3.7/site-packages/airflow/operators/python.py", line 185, in execute_callable
    return self.python_callable(*self.op_args, **self.op_kwargs)
  File "/opt/airflow/dags/ingest_data_dag.py", line 21, in ingest_call
    outparq = pd.read_parquet(filePath)
  File "/home/airflow/.local/lib/python3.7/site-packages/pandas/io/parquet.py", line 500, in read_parquet
    **kwargs,
  File "/home/airflow/.local/lib/python3.7/site-packages/pandas/io/parquet.py", line 240, in read
    path_or_handle, columns=columns, **kwargs
  File "/home/airflow/.local/lib/python3.7/site-packages/pyarrow/parquet.py", line 1869, in read_table
    coerce_int96_timestamp_unit=coerce_int96_timestamp_unit
  File "/home/airflow/.local/lib/python3.7/site-packages/pyarrow/parquet.py", line 1679, in __init__
    [fragment], schema=fragment.physical_schema,
  File "pyarrow/_dataset.pyx", line 952, in pyarrow._dataset.Fragment.physical_schema.__get__
  File "pyarrow/error.pxi", line 143, in pyarrow.lib.pyarrow_internal_check_status
  File "pyarrow/error.pxi", line 99, in pyarrow.lib.check_status
pyarrow.lib.ArrowInvalid: Could not open Parquet input source '<Buffer>': Parquet magic bytes not found in footer. Either the file is corrupted or this is not a parquet file.
[2022-09-11 12:09:28,554] {local_task_job.py:212} WARNING - State of this instance has been externally set to failed. Terminating instance.
[2022-09-11 12:09:28,558] {process_utils.py:124} INFO - Sending Signals.SIGTERM to group 19448. PIDs of all processes in the group: [19448]
[2022-09-11 12:09:28,559] {process_utils.py:75} INFO - Sending the signal Signals.SIGTERM to group 19448
[2022-09-11 12:09:28,584] {taskinstance.py:1408} ERROR - Received SIGTERM. Terminating subprocesses.
[2022-09-11 12:09:30,627] {process_utils.py:70} INFO - Process psutil.Process(pid=19448, status='terminated', exitcode=1, started='12:09:22') (19448) terminated with exit code 1
