[2022-09-11 16:54:59,610] {taskinstance.py:1032} INFO - Dependencies all met for <TaskInstance: FHVIngestionDag.ingest scheduled__2019-01-01T06:00:00+00:00 [queued]>
[2022-09-11 16:54:59,621] {taskinstance.py:1032} INFO - Dependencies all met for <TaskInstance: FHVIngestionDag.ingest scheduled__2019-01-01T06:00:00+00:00 [queued]>
[2022-09-11 16:54:59,621] {taskinstance.py:1238} INFO - 
--------------------------------------------------------------------------------
[2022-09-11 16:54:59,621] {taskinstance.py:1239} INFO - Starting attempt 5 of 5
[2022-09-11 16:54:59,622] {taskinstance.py:1240} INFO - 
--------------------------------------------------------------------------------
[2022-09-11 16:54:59,798] {taskinstance.py:1259} INFO - Executing <Task(PythonOperator): ingest> on 2019-01-01 06:00:00+00:00
[2022-09-11 16:54:59,803] {standard_task_runner.py:52} INFO - Started process 8514 to run task
[2022-09-11 16:54:59,806] {standard_task_runner.py:76} INFO - Running: ['***', 'tasks', 'run', 'FHVIngestionDag', 'ingest', 'scheduled__2019-01-01T06:00:00+00:00', '--job-id', '101', '--raw', '--subdir', 'DAGS_FOLDER/FHV_ingest_19.py', '--cfg-path', '/tmp/tmp16e7ryff', '--error-file', '/tmp/tmps3qhuk08']
[2022-09-11 16:54:59,807] {standard_task_runner.py:77} INFO - Job 101: Subtask ingest
[2022-09-11 16:54:59,984] {logging_mixin.py:109} INFO - Running <TaskInstance: FHVIngestionDag.ingest scheduled__2019-01-01T06:00:00+00:00 [running]> on host 6ae512137983
[2022-09-11 16:55:00,482] {logging_mixin.py:109} WARNING - /home/***/.local/lib/python3.7/site-packages/***/utils/context.py:152 AirflowContextDeprecationWarning: Accessing 'execution_date' from the template is deprecated and will be removed in a future version. Please use 'data_interval_start' or 'logical_date' instead.
[2022-09-11 16:55:00,506] {taskinstance.py:1426} INFO - Exporting the following env vars:
AIRFLOW_CTX_DAG_OWNER=***
AIRFLOW_CTX_DAG_ID=FHVIngestionDag
AIRFLOW_CTX_TASK_ID=ingest
AIRFLOW_CTX_EXECUTION_DATE=2019-01-01T06:00:00+00:00
AIRFLOW_CTX_DAG_RUN_ID=scheduled__2019-01-01T06:00:00+00:00
[2022-09-11 16:55:49,122] {local_task_job.py:154} INFO - Task exited with return code Negsignal.SIGKILL
[2022-09-11 16:55:49,147] {taskinstance.py:1277} INFO - Marking task as FAILED. dag_id=FHVIngestionDag, task_id=ingest, execution_date=20190101T060000, start_date=20220911T165459, end_date=20220911T165549
[2022-09-11 16:55:49,789] {local_task_job.py:264} INFO - 0 downstream tasks scheduled from follow-on schedule check
[2022-09-15 05:17:18,872] {taskinstance.py:1032} INFO - Dependencies all met for <TaskInstance: FHVIngestionDag.ingest scheduled__2019-01-01T06:00:00+00:00 [queued]>
[2022-09-15 05:17:18,951] {taskinstance.py:1032} INFO - Dependencies all met for <TaskInstance: FHVIngestionDag.ingest scheduled__2019-01-01T06:00:00+00:00 [queued]>
[2022-09-15 05:17:18,952] {taskinstance.py:1238} INFO - 
--------------------------------------------------------------------------------
[2022-09-15 05:17:18,952] {taskinstance.py:1239} INFO - Starting attempt 5 of 4
[2022-09-15 05:17:18,952] {taskinstance.py:1240} INFO - 
--------------------------------------------------------------------------------
[2022-09-15 05:17:19,041] {taskinstance.py:1259} INFO - Executing <Task(PythonOperator): ingest> on 2019-01-01 06:00:00+00:00
[2022-09-15 05:17:19,045] {standard_task_runner.py:52} INFO - Started process 218 to run task
[2022-09-15 05:17:19,051] {standard_task_runner.py:76} INFO - Running: ['***', 'tasks', 'run', 'FHVIngestionDag', 'ingest', 'scheduled__2019-01-01T06:00:00+00:00', '--job-id', '145', '--raw', '--subdir', 'DAGS_FOLDER/FHV_ingest_19.py', '--cfg-path', '/tmp/tmpjpvr8ny0', '--error-file', '/tmp/tmp9nzhq17b']
[2022-09-15 05:17:19,052] {standard_task_runner.py:77} INFO - Job 145: Subtask ingest
[2022-09-15 05:17:19,219] {logging_mixin.py:109} INFO - Running <TaskInstance: FHVIngestionDag.ingest scheduled__2019-01-01T06:00:00+00:00 [running]> on host c071d865a623
[2022-09-15 05:17:19,359] {logging_mixin.py:109} WARNING - /home/***/.local/lib/python3.7/site-packages/***/utils/context.py:152 AirflowContextDeprecationWarning: Accessing 'execution_date' from the template is deprecated and will be removed in a future version. Please use 'data_interval_start' or 'logical_date' instead.
[2022-09-15 05:17:19,484] {taskinstance.py:1426} INFO - Exporting the following env vars:
AIRFLOW_CTX_DAG_OWNER=***
AIRFLOW_CTX_DAG_ID=FHVIngestionDag
AIRFLOW_CTX_TASK_ID=ingest
AIRFLOW_CTX_EXECUTION_DATE=2019-01-01T06:00:00+00:00
AIRFLOW_CTX_DAG_RUN_ID=scheduled__2019-01-01T06:00:00+00:00
[2022-09-15 05:17:19,485] {logging_mixin.py:109} INFO - 3
[2022-09-15 05:17:42,069] {logging_mixin.py:109} INFO - /opt/***/FHV_OUT_2019-01.parquet
[2022-09-15 05:17:43,992] {logging_mixin.py:109} INFO -   dispatching_base_num     pickup_datetime  ... SR_Flag  Affiliated_base_number
0               B00001 2019-01-01 00:30:00  ...     NaN                  B00001
1               B00001 2019-01-01 00:45:00  ...     NaN                  B00001
2               B00001 2019-01-01 00:15:00  ...     NaN                  B00001
3               B00008 2019-01-01 00:19:00  ...     NaN                  B00008
4               B00008 2019-01-01 00:27:00  ...     NaN                  B00008

[5 rows x 7 columns]
[2022-09-15 05:18:17,091] {taskinstance.py:1700} ERROR - Task failed with exception
Traceback (most recent call last):
  File "/home/airflow/.local/lib/python3.7/site-packages/sqlalchemy/engine/base.py", line 2336, in _wrap_pool_connect
    return fn()
  File "/home/airflow/.local/lib/python3.7/site-packages/sqlalchemy/pool/base.py", line 364, in connect
    return _ConnectionFairy._checkout(self)
  File "/home/airflow/.local/lib/python3.7/site-packages/sqlalchemy/pool/base.py", line 778, in _checkout
    fairy = _ConnectionRecord.checkout(pool)
  File "/home/airflow/.local/lib/python3.7/site-packages/sqlalchemy/pool/base.py", line 495, in checkout
    rec = pool._do_get()
  File "/home/airflow/.local/lib/python3.7/site-packages/sqlalchemy/pool/impl.py", line 140, in _do_get
    self._dec_overflow()
  File "/home/airflow/.local/lib/python3.7/site-packages/sqlalchemy/util/langhelpers.py", line 70, in __exit__
    with_traceback=exc_tb,
  File "/home/airflow/.local/lib/python3.7/site-packages/sqlalchemy/util/compat.py", line 182, in raise_
    raise exception
  File "/home/airflow/.local/lib/python3.7/site-packages/sqlalchemy/pool/impl.py", line 137, in _do_get
    return self._create_connection()
  File "/home/airflow/.local/lib/python3.7/site-packages/sqlalchemy/pool/base.py", line 309, in _create_connection
    return _ConnectionRecord(self)
  File "/home/airflow/.local/lib/python3.7/site-packages/sqlalchemy/pool/base.py", line 440, in __init__
    self.__connect(first_connect_check=True)
  File "/home/airflow/.local/lib/python3.7/site-packages/sqlalchemy/pool/base.py", line 661, in __connect
    pool.logger.debug("Error on connect(): %s", e)
  File "/home/airflow/.local/lib/python3.7/site-packages/sqlalchemy/util/langhelpers.py", line 70, in __exit__
    with_traceback=exc_tb,
  File "/home/airflow/.local/lib/python3.7/site-packages/sqlalchemy/util/compat.py", line 182, in raise_
    raise exception
  File "/home/airflow/.local/lib/python3.7/site-packages/sqlalchemy/pool/base.py", line 656, in __connect
    connection = pool._invoke_creator(self)
  File "/home/airflow/.local/lib/python3.7/site-packages/sqlalchemy/engine/strategies.py", line 114, in connect
    return dialect.connect(*cargs, **cparams)
  File "/home/airflow/.local/lib/python3.7/site-packages/sqlalchemy/engine/default.py", line 508, in connect
    return self.dbapi.connect(*cargs, **cparams)
  File "/home/airflow/.local/lib/python3.7/site-packages/psycopg2/__init__.py", line 122, in connect
    conn = _connect(dsn, connection_factory=connection_factory, **kwasync)
psycopg2.OperationalError: could not translate host name "pgdatabase" to address: Temporary failure in name resolution


The above exception was the direct cause of the following exception:

Traceback (most recent call last):
  File "/home/airflow/.local/lib/python3.7/site-packages/airflow/models/taskinstance.py", line 1329, in _run_raw_task
    self._execute_task_with_callbacks(context)
  File "/home/airflow/.local/lib/python3.7/site-packages/airflow/models/taskinstance.py", line 1455, in _execute_task_with_callbacks
    result = self._execute_task(context, self.task)
  File "/home/airflow/.local/lib/python3.7/site-packages/airflow/models/taskinstance.py", line 1511, in _execute_task
    result = execute_callable(context=context)
  File "/home/airflow/.local/lib/python3.7/site-packages/airflow/operators/python.py", line 174, in execute
    return_value = self.execute_callable()
  File "/home/airflow/.local/lib/python3.7/site-packages/airflow/operators/python.py", line 185, in execute_callable
    return self.python_callable(*self.op_args, **self.op_kwargs)
  File "/opt/airflow/dags/FHV_ingest_19.py", line 30, in ingest_call
    outparq.to_sql(name= table_name, con=engine, if_exists='replace')
  File "/home/airflow/.local/lib/python3.7/site-packages/pandas/core/generic.py", line 2882, in to_sql
    method=method,
  File "/home/airflow/.local/lib/python3.7/site-packages/pandas/io/sql.py", line 728, in to_sql
    **engine_kwargs,
  File "/home/airflow/.local/lib/python3.7/site-packages/pandas/io/sql.py", line 1758, in to_sql
    dtype=dtype,
  File "/home/airflow/.local/lib/python3.7/site-packages/pandas/io/sql.py", line 1650, in prep_table
    table.create()
  File "/home/airflow/.local/lib/python3.7/site-packages/pandas/io/sql.py", line 856, in create
    if self.exists():
  File "/home/airflow/.local/lib/python3.7/site-packages/pandas/io/sql.py", line 840, in exists
    return self.pd_sql.has_table(self.name, self.schema)
  File "/home/airflow/.local/lib/python3.7/site-packages/pandas/io/sql.py", line 1787, in has_table
    self.connectable.dialect.has_table, name, schema or self.meta.schema
  File "/home/airflow/.local/lib/python3.7/site-packages/sqlalchemy/engine/base.py", line 2211, in run_callable
    with self._contextual_connect() as conn:
  File "/home/airflow/.local/lib/python3.7/site-packages/sqlalchemy/engine/base.py", line 2302, in _contextual_connect
    self._wrap_pool_connect(self.pool.connect, None),
  File "/home/airflow/.local/lib/python3.7/site-packages/sqlalchemy/engine/base.py", line 2340, in _wrap_pool_connect
    e, dialect, self
  File "/home/airflow/.local/lib/python3.7/site-packages/sqlalchemy/engine/base.py", line 1584, in _handle_dbapi_exception_noconnection
    sqlalchemy_exception, with_traceback=exc_info[2], from_=e
  File "/home/airflow/.local/lib/python3.7/site-packages/sqlalchemy/util/compat.py", line 182, in raise_
    raise exception
  File "/home/airflow/.local/lib/python3.7/site-packages/sqlalchemy/engine/base.py", line 2336, in _wrap_pool_connect
    return fn()
  File "/home/airflow/.local/lib/python3.7/site-packages/sqlalchemy/pool/base.py", line 364, in connect
    return _ConnectionFairy._checkout(self)
  File "/home/airflow/.local/lib/python3.7/site-packages/sqlalchemy/pool/base.py", line 778, in _checkout
    fairy = _ConnectionRecord.checkout(pool)
  File "/home/airflow/.local/lib/python3.7/site-packages/sqlalchemy/pool/base.py", line 495, in checkout
    rec = pool._do_get()
  File "/home/airflow/.local/lib/python3.7/site-packages/sqlalchemy/pool/impl.py", line 140, in _do_get
    self._dec_overflow()
  File "/home/airflow/.local/lib/python3.7/site-packages/sqlalchemy/util/langhelpers.py", line 70, in __exit__
    with_traceback=exc_tb,
  File "/home/airflow/.local/lib/python3.7/site-packages/sqlalchemy/util/compat.py", line 182, in raise_
    raise exception
  File "/home/airflow/.local/lib/python3.7/site-packages/sqlalchemy/pool/impl.py", line 137, in _do_get
    return self._create_connection()
  File "/home/airflow/.local/lib/python3.7/site-packages/sqlalchemy/pool/base.py", line 309, in _create_connection
    return _ConnectionRecord(self)
  File "/home/airflow/.local/lib/python3.7/site-packages/sqlalchemy/pool/base.py", line 440, in __init__
    self.__connect(first_connect_check=True)
  File "/home/airflow/.local/lib/python3.7/site-packages/sqlalchemy/pool/base.py", line 661, in __connect
    pool.logger.debug("Error on connect(): %s", e)
  File "/home/airflow/.local/lib/python3.7/site-packages/sqlalchemy/util/langhelpers.py", line 70, in __exit__
    with_traceback=exc_tb,
  File "/home/airflow/.local/lib/python3.7/site-packages/sqlalchemy/util/compat.py", line 182, in raise_
    raise exception
  File "/home/airflow/.local/lib/python3.7/site-packages/sqlalchemy/pool/base.py", line 656, in __connect
    connection = pool._invoke_creator(self)
  File "/home/airflow/.local/lib/python3.7/site-packages/sqlalchemy/engine/strategies.py", line 114, in connect
    return dialect.connect(*cargs, **cparams)
  File "/home/airflow/.local/lib/python3.7/site-packages/sqlalchemy/engine/default.py", line 508, in connect
    return self.dbapi.connect(*cargs, **cparams)
  File "/home/airflow/.local/lib/python3.7/site-packages/psycopg2/__init__.py", line 122, in connect
    conn = _connect(dsn, connection_factory=connection_factory, **kwasync)
sqlalchemy.exc.OperationalError: (psycopg2.OperationalError) could not translate host name "pgdatabase" to address: Temporary failure in name resolution

(Background on this error at: http://sqlalche.me/e/13/e3q8)
[2022-09-15 05:18:26,307] {taskinstance.py:1277} INFO - Marking task as FAILED. dag_id=FHVIngestionDag, task_id=ingest, execution_date=20190101T060000, start_date=20220915T051718, end_date=20220915T051826
[2022-09-15 05:18:27,511] {standard_task_runner.py:92} ERROR - Failed to execute job 145 for task ingest
Traceback (most recent call last):
  File "/home/airflow/.local/lib/python3.7/site-packages/sqlalchemy/engine/base.py", line 2336, in _wrap_pool_connect
    return fn()
  File "/home/airflow/.local/lib/python3.7/site-packages/sqlalchemy/pool/base.py", line 364, in connect
    return _ConnectionFairy._checkout(self)
  File "/home/airflow/.local/lib/python3.7/site-packages/sqlalchemy/pool/base.py", line 778, in _checkout
    fairy = _ConnectionRecord.checkout(pool)
  File "/home/airflow/.local/lib/python3.7/site-packages/sqlalchemy/pool/base.py", line 495, in checkout
    rec = pool._do_get()
  File "/home/airflow/.local/lib/python3.7/site-packages/sqlalchemy/pool/impl.py", line 140, in _do_get
    self._dec_overflow()
  File "/home/airflow/.local/lib/python3.7/site-packages/sqlalchemy/util/langhelpers.py", line 70, in __exit__
    with_traceback=exc_tb,
  File "/home/airflow/.local/lib/python3.7/site-packages/sqlalchemy/util/compat.py", line 182, in raise_
    raise exception
  File "/home/airflow/.local/lib/python3.7/site-packages/sqlalchemy/pool/impl.py", line 137, in _do_get
    return self._create_connection()
  File "/home/airflow/.local/lib/python3.7/site-packages/sqlalchemy/pool/base.py", line 309, in _create_connection
    return _ConnectionRecord(self)
  File "/home/airflow/.local/lib/python3.7/site-packages/sqlalchemy/pool/base.py", line 440, in __init__
    self.__connect(first_connect_check=True)
  File "/home/airflow/.local/lib/python3.7/site-packages/sqlalchemy/pool/base.py", line 661, in __connect
    pool.logger.debug("Error on connect(): %s", e)
  File "/home/airflow/.local/lib/python3.7/site-packages/sqlalchemy/util/langhelpers.py", line 70, in __exit__
    with_traceback=exc_tb,
  File "/home/airflow/.local/lib/python3.7/site-packages/sqlalchemy/util/compat.py", line 182, in raise_
    raise exception
  File "/home/airflow/.local/lib/python3.7/site-packages/sqlalchemy/pool/base.py", line 656, in __connect
    connection = pool._invoke_creator(self)
  File "/home/airflow/.local/lib/python3.7/site-packages/sqlalchemy/engine/strategies.py", line 114, in connect
    return dialect.connect(*cargs, **cparams)
  File "/home/airflow/.local/lib/python3.7/site-packages/sqlalchemy/engine/default.py", line 508, in connect
    return self.dbapi.connect(*cargs, **cparams)
  File "/home/airflow/.local/lib/python3.7/site-packages/psycopg2/__init__.py", line 122, in connect
    conn = _connect(dsn, connection_factory=connection_factory, **kwasync)
psycopg2.OperationalError: could not translate host name "pgdatabase" to address: Temporary failure in name resolution


The above exception was the direct cause of the following exception:

Traceback (most recent call last):
  File "/home/airflow/.local/lib/python3.7/site-packages/airflow/task/task_runner/standard_task_runner.py", line 85, in _start_by_fork
    args.func(args, dag=self.dag)
  File "/home/airflow/.local/lib/python3.7/site-packages/airflow/cli/cli_parser.py", line 48, in command
    return func(*args, **kwargs)
  File "/home/airflow/.local/lib/python3.7/site-packages/airflow/utils/cli.py", line 92, in wrapper
    return f(*args, **kwargs)
  File "/home/airflow/.local/lib/python3.7/site-packages/airflow/cli/commands/task_command.py", line 298, in task_run
    _run_task_by_selected_method(args, dag, ti)
  File "/home/airflow/.local/lib/python3.7/site-packages/airflow/cli/commands/task_command.py", line 107, in _run_task_by_selected_method
    _run_raw_task(args, ti)
  File "/home/airflow/.local/lib/python3.7/site-packages/airflow/cli/commands/task_command.py", line 184, in _run_raw_task
    error_file=args.error_file,
  File "/home/airflow/.local/lib/python3.7/site-packages/airflow/utils/session.py", line 70, in wrapper
    return func(*args, session=session, **kwargs)
  File "/home/airflow/.local/lib/python3.7/site-packages/airflow/models/taskinstance.py", line 1329, in _run_raw_task
    self._execute_task_with_callbacks(context)
  File "/home/airflow/.local/lib/python3.7/site-packages/airflow/models/taskinstance.py", line 1455, in _execute_task_with_callbacks
    result = self._execute_task(context, self.task)
  File "/home/airflow/.local/lib/python3.7/site-packages/airflow/models/taskinstance.py", line 1511, in _execute_task
    result = execute_callable(context=context)
  File "/home/airflow/.local/lib/python3.7/site-packages/airflow/operators/python.py", line 174, in execute
    return_value = self.execute_callable()
  File "/home/airflow/.local/lib/python3.7/site-packages/airflow/operators/python.py", line 185, in execute_callable
    return self.python_callable(*self.op_args, **self.op_kwargs)
  File "/opt/airflow/dags/FHV_ingest_19.py", line 30, in ingest_call
    outparq.to_sql(name= table_name, con=engine, if_exists='replace')
  File "/home/airflow/.local/lib/python3.7/site-packages/pandas/core/generic.py", line 2882, in to_sql
    method=method,
  File "/home/airflow/.local/lib/python3.7/site-packages/pandas/io/sql.py", line 728, in to_sql
    **engine_kwargs,
  File "/home/airflow/.local/lib/python3.7/site-packages/pandas/io/sql.py", line 1758, in to_sql
    dtype=dtype,
  File "/home/airflow/.local/lib/python3.7/site-packages/pandas/io/sql.py", line 1650, in prep_table
    table.create()
  File "/home/airflow/.local/lib/python3.7/site-packages/pandas/io/sql.py", line 856, in create
    if self.exists():
  File "/home/airflow/.local/lib/python3.7/site-packages/pandas/io/sql.py", line 840, in exists
    return self.pd_sql.has_table(self.name, self.schema)
  File "/home/airflow/.local/lib/python3.7/site-packages/pandas/io/sql.py", line 1787, in has_table
    self.connectable.dialect.has_table, name, schema or self.meta.schema
  File "/home/airflow/.local/lib/python3.7/site-packages/sqlalchemy/engine/base.py", line 2211, in run_callable
    with self._contextual_connect() as conn:
  File "/home/airflow/.local/lib/python3.7/site-packages/sqlalchemy/engine/base.py", line 2302, in _contextual_connect
    self._wrap_pool_connect(self.pool.connect, None),
  File "/home/airflow/.local/lib/python3.7/site-packages/sqlalchemy/engine/base.py", line 2340, in _wrap_pool_connect
    e, dialect, self
  File "/home/airflow/.local/lib/python3.7/site-packages/sqlalchemy/engine/base.py", line 1584, in _handle_dbapi_exception_noconnection
    sqlalchemy_exception, with_traceback=exc_info[2], from_=e
  File "/home/airflow/.local/lib/python3.7/site-packages/sqlalchemy/util/compat.py", line 182, in raise_
    raise exception
  File "/home/airflow/.local/lib/python3.7/site-packages/sqlalchemy/engine/base.py", line 2336, in _wrap_pool_connect
    return fn()
  File "/home/airflow/.local/lib/python3.7/site-packages/sqlalchemy/pool/base.py", line 364, in connect
    return _ConnectionFairy._checkout(self)
  File "/home/airflow/.local/lib/python3.7/site-packages/sqlalchemy/pool/base.py", line 778, in _checkout
    fairy = _ConnectionRecord.checkout(pool)
  File "/home/airflow/.local/lib/python3.7/site-packages/sqlalchemy/pool/base.py", line 495, in checkout
    rec = pool._do_get()
  File "/home/airflow/.local/lib/python3.7/site-packages/sqlalchemy/pool/impl.py", line 140, in _do_get
    self._dec_overflow()
  File "/home/airflow/.local/lib/python3.7/site-packages/sqlalchemy/util/langhelpers.py", line 70, in __exit__
    with_traceback=exc_tb,
  File "/home/airflow/.local/lib/python3.7/site-packages/sqlalchemy/util/compat.py", line 182, in raise_
    raise exception
  File "/home/airflow/.local/lib/python3.7/site-packages/sqlalchemy/pool/impl.py", line 137, in _do_get
    return self._create_connection()
  File "/home/airflow/.local/lib/python3.7/site-packages/sqlalchemy/pool/base.py", line 309, in _create_connection
    return _ConnectionRecord(self)
  File "/home/airflow/.local/lib/python3.7/site-packages/sqlalchemy/pool/base.py", line 440, in __init__
    self.__connect(first_connect_check=True)
  File "/home/airflow/.local/lib/python3.7/site-packages/sqlalchemy/pool/base.py", line 661, in __connect
    pool.logger.debug("Error on connect(): %s", e)
  File "/home/airflow/.local/lib/python3.7/site-packages/sqlalchemy/util/langhelpers.py", line 70, in __exit__
    with_traceback=exc_tb,
  File "/home/airflow/.local/lib/python3.7/site-packages/sqlalchemy/util/compat.py", line 182, in raise_
    raise exception
  File "/home/airflow/.local/lib/python3.7/site-packages/sqlalchemy/pool/base.py", line 656, in __connect
    connection = pool._invoke_creator(self)
  File "/home/airflow/.local/lib/python3.7/site-packages/sqlalchemy/engine/strategies.py", line 114, in connect
    return dialect.connect(*cargs, **cparams)
  File "/home/airflow/.local/lib/python3.7/site-packages/sqlalchemy/engine/default.py", line 508, in connect
    return self.dbapi.connect(*cargs, **cparams)
  File "/home/airflow/.local/lib/python3.7/site-packages/psycopg2/__init__.py", line 122, in connect
    conn = _connect(dsn, connection_factory=connection_factory, **kwasync)
sqlalchemy.exc.OperationalError: (psycopg2.OperationalError) could not translate host name "pgdatabase" to address: Temporary failure in name resolution

(Background on this error at: http://sqlalche.me/e/13/e3q8)
[2022-09-15 05:18:29,969] {local_task_job.py:154} INFO - Task exited with return code 1
[2022-09-15 05:18:30,250] {local_task_job.py:264} INFO - 0 downstream tasks scheduled from follow-on schedule check
